<?xml version="1.0" ?>
<!-- =================================================================================== -->
<!-- |    This document was autogenerated by xacro from /home/sdries/ros/groovy/tue/trunk/amigo2_common/amigo2_description/scripts/../urdf/xacro/amigo2.urdf.xacro | -->
<!-- |    EDITING THIS FILE BY HAND IS NOT RECOMMENDED                                 | -->
<!-- =================================================================================== -->
<robot name="amigo" xmlns:controller="http://playerstage.sourceforge.net/gazebo/xmlschema/#controller" xmlns:interface="http://playerstage.sourceforge.net/gazebo/xmlschema/#interface" xmlns:sensor="http://playerstage.sourceforge.net/gazebo/xmlschema/#sensor" xmlns:xacro="http://ros.org/wiki/xacro">
  <!--xmlns:sensor="http://playerstage.sourceforge.net/gazebo/xmlschema/#sensor"
       xmlns:controller="http://playerstage.sourceforge.net/gazebo/xmlschema/#controller"
       xmlns:interface="http://playerstage.sourceforge.net/gazebo/xmlschema/#interface">-->
  <author>Janno Lunenburg</author>
  <license>BSD</license>
  <review notes="" status="unreviewed"/>
  <!-- ToDo: In general: look at DH conventions-->
  <!--get link & joint definitions -->
  <!--Definitions from default package?-->
  <!--get link & joint definitions -->
  <!--<include filename="$(find amigo_robot_model)/description/definitions.xacro" />-->
  <author>Kris van Tienhoven</author>
  <license>BSD</license>
  <review notes="" status="unreviewed"/>
  <!--get custom materials -->
  <!--<include filename="$(find amigo_robot_model)/description/materials.urdf.xacro" />-->
  <author>Kris van Tienhoven</author>
  <license>BSD</license>
  <review notes="" status="unreviewed"/>
  <material name="Blue">
    <color rgba="0.0 0.0 0.8 1.0"/>
  </material>
  <material name="Green">
    <color rgba="0.0 0.8 0.0 1.0"/>
  </material>
  <material name="Grey">
    <color rgba="0.7 0.7 0.7 1.0"/>
  </material>
  <material name="Grey2">
    <color rgba="0.9 0.9 0.9 1.0"/>
  </material>
  <material name="Red">
    <color rgba="0.8 0.0 0.0 1.0"/>
  </material>
  <material name="White">
    <color rgba="1.0 1.0 1.0 1.0"/>
  </material>
  <material name="Black">
    <color rgba="0.1 0.1 0.1 1.0"/>
  </material>
  <material name="LightGrey">
    <color rgba="0.6 0.6 0.6 1.0"/>
  </material>
  <material name="amigo_description/bottomcovers">
    <texture filename="package://amigo_description/media/materials/textures/bottomcovers/finalreduced.jpg"/>
  </material>
  <material name="amigo_description/white">
    <texture filename="package://amigo_description/media/materials/textures/white/white.jpg"/>
  </material>
  <material name="amigo_description/logo">
    <texture filename="package://amigo_description/media/materials/textures/logo/tue.jpg"/>
  </material>
  <material name="amigo_description/aluminium">
    <texture filename="package://amigo_description/media/materials/textures/aluminium/aluminium_0001_c.jpg"/>
  </material>
  <material name="amigo_description/orange">
    <texture filename="package://amigo_description/media/materials/textures/orange/orange.jpg"/>
  </material>
  <!--========BUILD BASE======-->
  <author>Janno Lunenburg</author>
  <license>BSD</license>
  <review notes="" status="unreviewed"/>
  <link name="base_link">
    <inertial>
      <origin rpy="0 0 0" xyz="0.0 0.0 0.0"/>
      <mass value="0"/>
      <inertia ixx="0" ixy="0" ixz="0" iyy="0" iyz="0" izz="0"/>
    </inertial>
    <visual>
      <origin rpy="0 0 0" xyz="0.0 0.0 0.0"/>
      <geometry>
        <cylinder length="0.00" radius="0.0"/>
      </geometry>
      <material name="White">
     </material>
    </visual>
    <collision>
      <origin rpy="0 0 0" xyz="0.0 0.0 0.0"/>
      <geometry>
        <cylinder length="0.00" radius="0.0"/>
      </geometry>
    </collision>
  </link>
  <gazebo reference="base_link">
    <material>Gazebo/White</material>
    <turnGravityOff>false</turnGravityOff>
  </gazebo>
  <link name="base">
    <inertial>
      <origin rpy="0 0 0" xyz="0.0 0.0 0.0"/>
      <mass value="0.1"/>
      <inertia ixx="0.001" ixy="0" ixz="0" iyy="0.001" iyz="0" izz="0.001"/>
    </inertial>
    <visual>
      <origin rpy="0 0 0" xyz="0.0 0.0 0.0"/>
      <geometry>
        <box size="0.700 0.500 0.1"/>
      </geometry>
      <material name="White">
     </material>
    </visual>
    <collision>
      <origin rpy="0 0 0" xyz="0.0 0.0 0.0"/>
      <geometry>
        <box size="0.700 0.500 0.1"/>
      </geometry>
    </collision>
  </link>
  <gazebo reference="base">
    <material>Gazebo/White</material>
    <turnGravityOff>false</turnGravityOff>
  </gazebo>
  <link name="sidepot_left">
    <inertial>
      <origin rpy="0 0 0" xyz="0.0 0.0 0.0"/>
      <mass value="0.1"/>
      <inertia ixx="0.001" ixy="0" ixz="0" iyy="0.001" iyz="0" izz="0.001"/>
    </inertial>
    <visual>
      <origin rpy="0 0 0" xyz="0.0 0.0 0.0"/>
      <geometry>
        <box size="0.400 0.050 0.1"/>
      </geometry>
      <material name="White">
     </material>
    </visual>
    <collision>
      <origin rpy="0 0 0" xyz="0.0 0.0 0.0"/>
      <geometry>
        <box size="0.400 0.050 0.1"/>
      </geometry>
    </collision>
  </link>
  <gazebo reference="sidepot_left">
    <material>Gazebo/White</material>
    <turnGravityOff>false</turnGravityOff>
  </gazebo>
  <link name="sidepot_right">
    <inertial>
      <origin rpy="0 0 0" xyz="0.0 0.0 0.0"/>
      <mass value="0.1"/>
      <inertia ixx="0.001" ixy="0" ixz="0" iyy="0.001" iyz="0" izz="0.001"/>
    </inertial>
    <visual>
      <origin rpy="0 0 0" xyz="0.0 0.0 0.0"/>
      <geometry>
        <box size="0.400 0.050 0.1"/>
      </geometry>
      <material name="White">
     </material>
    </visual>
    <collision>
      <origin rpy="0 0 0" xyz="0.0 0.0 0.0"/>
      <geometry>
        <box size="0.400 0.050 0.1"/>
      </geometry>
    </collision>
  </link>
  <gazebo reference="sidepot_right">
    <material>Gazebo/White</material>
    <turnGravityOff>false</turnGravityOff>
  </gazebo>
  <link name="base_torso_mount">
    <inertial>
      <origin rpy="0 0 0" xyz="0.0 0.0 0.0"/>
      <mass value="0"/>
      <inertia ixx="0" ixy="0" ixz="0" iyy="0" iyz="0" izz="0"/>
    </inertial>
    <visual>
      <origin rpy="0 0 0" xyz="0.0 0.0 0.0"/>
      <geometry>
        <cylinder length="0.00" radius="0.0"/>
      </geometry>
      <material name="White">
     </material>
    </visual>
    <collision>
      <origin rpy="0 0 0" xyz="0.0 0.0 0.0"/>
      <geometry>
        <cylinder length="0.00" radius="0.0"/>
      </geometry>
    </collision>
  </link>
  <gazebo reference="base_torso_mount">
    <material>Gazebo/White</material>
    <turnGravityOff>false</turnGravityOff>
  </gazebo>
  <joint name="base_link_joint" type="fixed">
    <parent link="base_link"/>
    <child link="base"/>
    <axis xyz="1 0 0"/>
    <origin rpy="0 0 0" xyz="0.0 0.0 0.075"/>
    <!--ToDO: adjust height-->
  </joint>
  <joint name="sidepot_left_joint" type="fixed">
    <parent link="base"/>
    <child link="sidepot_left"/>
    <axis xyz="1 0 0"/>
    <origin rpy="0 0 0" xyz="0.0 0.275 0.0"/>
    <!--ToDO: adjust distance-->
  </joint>
  <joint name="sidepot_right_joint" type="fixed">
    <parent link="base"/>
    <child link="sidepot_right"/>
    <axis xyz="1 0 0"/>
    <origin rpy="0 0 0" xyz="0.0 -0.275 0.0"/>
    <!--ToDO: adjust distance-->
  </joint>
  <joint name="base_mount_joint" type="fixed">
    <parent link="base"/>
    <child link="base_torso_mount"/>
    <origin rpy="0 0 0.0" xyz="0.0 0.0 0.05"/>
    <!--ToDo: adjust height-->
  </joint>
  <!--========BUILD TORSO======-->
  <author>Rob Janssen, Kris van Tienhoven</author>
  <license>BSD</license>
  <review notes="" status="unreviewed"/>
  <link name="torso_mounting_frame">
    <inertial>
      <origin rpy="0 0 0" xyz="0.0 0.0 0.025"/>
      <mass value="0.1"/>
      <inertia ixx="0.001" ixy="0" ixz="0" iyy="0.001" iyz="0" izz="0.001"/>
    </inertial>
    <visual>
      <origin rpy="0 0 0" xyz="0.0 0.0 0.025"/>
      <geometry>
        <box size="0.500 0.400 0.05"/>
      </geometry>
      <material name="White">
     </material>
    </visual>
    <collision>
      <origin rpy="0 0 0" xyz="0.0 0.0 0.025"/>
      <geometry>
        <box size="0.500 0.400 0.05"/>
      </geometry>
    </collision>
  </link>
  <gazebo reference="torso_mounting_frame">
    <material>Gazebo/White</material>
    <turnGravityOff>false</turnGravityOff>
  </gazebo>
  <link name="lower_rear_leg">
    <inertial>
      <origin rpy="0 0 0" xyz="0.195 0.0 0.0"/>
      <mass value="5"/>
      <inertia ixx="0.001" ixy="0" ixz="0" iyy="0.001" iyz="0" izz="0.001"/>
    </inertial>
    <visual>
      <origin rpy="0 0 0" xyz="0.195 0.0 0.0"/>
      <geometry>
        <box size="0.390 0.200 0.05"/>
      </geometry>
      <material name="White">
     </material>
    </visual>
    <collision>
      <origin rpy="0 0 0" xyz="0.195 0.0 0.0"/>
      <geometry>
        <box size="0.390 0.200 0.05"/>
      </geometry>
    </collision>
  </link>
  <gazebo reference="lower_rear_leg">
    <material>Gazebo/White</material>
    <turnGravityOff>false</turnGravityOff>
  </gazebo>
  <link name="upper_leg">
    <inertial>
      <origin rpy="0 0 0" xyz="0.20575 0.0 0.0"/>
      <mass value="5"/>
      <inertia ixx="0.001" ixy="0" ixz="0" iyy="0.001" iyz="0" izz="0.001"/>
    </inertial>
    <visual>
      <origin rpy="0 0 0" xyz="0.20575 0.0 0.0"/>
      <geometry>
        <box size="0.4115 0.200 0.1"/>
      </geometry>
      <material name="White">
     </material>
    </visual>
    <collision>
      <origin rpy="0 0 0" xyz="0.20575 0.0 0.0"/>
      <geometry>
        <box size="0.4115 0.200 0.1"/>
      </geometry>
    </collision>
  </link>
  <gazebo reference="upper_leg">
    <material>Gazebo/White</material>
    <turnGravityOff>false</turnGravityOff>
  </gazebo>
  <link name="trunk">
    <inertial>
      <origin rpy="0 0 0" xyz="0.2225 0.0 0.0"/>
      <mass value="10"/>
      <inertia ixx="0.001" ixy="0" ixz="0" iyy="0.001" iyz="0" izz="0.001"/>
    </inertial>
    <visual>
      <origin rpy="0 0 0" xyz="0.2225 0.0 0.0"/>
      <geometry>
        <box size="0.445 0.200 0.15"/>
      </geometry>
      <material name="White">
     </material>
    </visual>
    <collision>
      <origin rpy="0 0 0" xyz="0.2225 0.0 0.0"/>
      <geometry>
        <box size="0.445 0.200 0.15"/>
      </geometry>
    </collision>
  </link>
  <gazebo reference="trunk">
    <material>Gazebo/White</material>
    <turnGravityOff>false</turnGravityOff>
  </gazebo>
  <joint name="torso_mount_joint" type="fixed">
    <parent link="base_torso_mount"/>
    <child link="torso_mounting_frame"/>
    <origin rpy="0 0 0.0" xyz="0.0 0.0 0.0"/>
    <!--ToDo: adjust height-->
  </joint>
  <joint name="ankle_joint" type="revolute">
    <parent link="torso_mounting_frame"/>
    <child link="lower_rear_leg"/>
    <origin rpy="0 0 0" xyz="-0.185 0.0 0.045"/>
    <axis xyz="0 -1 0"/>
    <dynamics damping="6.0" friction="4.87"/>
    <limit effort="1000" lower="0.0" upper="1.57" velocity="10"/>
  </joint>
  <joint name="knee_joint" type="revolute">
    <parent link="lower_rear_leg"/>
    <child link="upper_leg"/>
    <origin rpy="3.14 3.14 0" xyz="0.390 0.0 0."/>
    <axis xyz="0 -1 0"/>
    <dynamics damping="6.0" friction="4.87"/>
    <limit effort="1000" lower="0.0" upper="1.57" velocity="10"/>
  </joint>
  <joint name="hip_joint" type="revolute">
    <parent link="upper_leg"/>
    <child link="trunk"/>
    <origin rpy="3.14 3.14 0" xyz="0.4115 0.0 0."/>
    <axis xyz="0 -1 0"/>
    <dynamics damping="6.0" friction="4.87"/>
    <limit effort="1000" lower="0.0" upper="1.57" velocity="10"/>
  </joint>
  <!--========BUILD ARMS======-->
  <author>Rob Janssen, Kris van Tienhoven, Janno Lunenburg</author>
  <license>BSD</license>
  <review notes="" status="unreviewed"/>
  <link name="shoulder_mount_right">
    <inertial>
      <origin rpy="1.57 0 0" xyz="0.0 -0.155 0.0"/>
      <mass value="0.15"/>
      <inertia ixx="0.01" ixy="0" ixz="0" iyy="0.01" iyz="0" izz="0.01"/>
    </inertial>
    <visual>
      <origin rpy="1.57 0 0 " xyz="0.0 -0.155 0.0"/>
      <geometry>
        <cylinder length="0.140" radius="0.075"/>
      </geometry>
      <material name="White">
     </material>
    </visual>
    <collision>
      <origin rpy="1.57 0 0 " xyz="0.0 -0.155 0.0"/>
      <geometry>
        <cylinder length="0.140" radius="0.075"/>
      </geometry>
    </collision>
  </link>
  <gazebo reference="shoulder_mount_right">
    <material>Gazebo/White</material>
    <turnGravityOff>false</turnGravityOff>
  </gazebo>
  <link name="shoulder_link1_right">
    <inertial>
      <origin rpy="0 0 0" xyz="0.0 0.0 0.0"/>
      <mass value="0.25"/>
      <inertia ixx="6.0" ixy="0" ixz="0" iyy="0.01" iyz="0" izz="0.01"/>
    </inertial>
    <visual>
      <origin rpy="0 0 0 " xyz="0.0 0.0 0.0525"/>
      <geometry>
        <cylinder length="0.015" radius="0.045"/>
      </geometry>
      <material name="Black">
     </material>
    </visual>
    <collision>
      <origin rpy="0 0 0 " xyz="0.0 0.0 0.0525"/>
      <geometry>
        <cylinder length="0.015" radius="0.045"/>
      </geometry>
    </collision>
  </link>
  <gazebo reference="shoulder_link1_right">
    <material>Gazebo/Black</material>
    <turnGravityOff>false</turnGravityOff>
  </gazebo>
  <link name="shoulder_link2_right">
    <inertial>
      <origin rpy="0 0 0" xyz="0.0 0.0 0.0"/>
      <mass value="0.15"/>
      <inertia ixx="0.01" ixy="0" ixz="0" iyy="4.04" iyz="0" izz="0.001"/>
    </inertial>
    <visual>
      <origin rpy="0 0 0" xyz="0.0 -0.06 -0.05"/>
      <geometry>
        <box size="0.035 0.01 0.1"/>
      </geometry>
      <material name="Black">
     </material>
    </visual>
    <collision>
      <origin rpy="0 0 0" xyz="0.0 -0.06 -0.05"/>
      <geometry>
        <box size="0.035 0.01 0.1"/>
      </geometry>
    </collision>
  </link>
  <gazebo reference="shoulder_link2_right">
    <material>Gazebo/Black</material>
    <turnGravityOff>false</turnGravityOff>
  </gazebo>
  <link name="upper_arm_right">
    <inertial>
      <origin rpy="0 0 0" xyz="0.0 -0.2 0.0"/>
      <mass value="2.95"/>
      <inertia ixx="0.027" ixy="0" ixz="0" iyy="0.45993" iyz="0" izz="0.004"/>
    </inertial>
    <visual>
      <origin rpy="0 0 3.1415" xyz="-0.00959 -0.19131 -0.00001"/>
      <geometry>
        <mesh filename="package://amigo_description/media/meshes/upperarmtextured.dae" scale="0.0004 0.0004 0.0004"/>
      </geometry>
      <material name="amigo_description/white"/>
    </visual>
    <collision>
      <origin rpy="0 0 3.1415" xyz="-0.00959 -0.19131 -0.00001"/>
      <geometry>
        <mesh filename="package://amigo_description/media/meshes/upperarmtextured.dae" scale="0.0004 0.0004 0.0004"/>
      </geometry>
    </collision>
  </link>
  <gazebo reference="upper_arm_right">
    <material>amigo_description/white</material>
    <turnGravityOff>false</turnGravityOff>
  </gazebo>
  <link name="elbow_link4_right">
    <inertial>
      <origin rpy="0 0 0" xyz="0.0 0.0 0.0"/>
      <mass value="0.1"/>
      <inertia ixx="0.001" ixy="0" ixz="0" iyy="0.6" iyz="0" izz="0.001"/>
    </inertial>
    <visual>
      <origin rpy="0 0 0" xyz="0.0 0.0 0.0"/>
      <geometry>
        <cylinder length="0.0" radius="0.0"/>
      </geometry>
      <material name="Grey">
     </material>
    </visual>
    <collision>
      <origin rpy="0 0 0" xyz="0.0 0.0 0.0"/>
      <geometry>
        <cylinder length="0.0" radius="0.0"/>
      </geometry>
    </collision>
  </link>
  <gazebo reference="elbow_link4_right">
    <material>Gazebo/Grey</material>
    <turnGravityOff>false</turnGravityOff>
  </gazebo>
  <link name="fore_arm_right">
    <inertial>
      <origin rpy="0.0 0 0" xyz="0.0 -0.14 0.0"/>
      <mass value="0.85"/>
      <inertia ixx="0.001" ixy="0" ixz="0" iyy="0.5" iyz="0" izz="0.001"/>
    </inertial>
    <visual>
      <origin rpy="0 -1.5708 0" xyz="0.00425 -0.14868 0.00547"/>
      <geometry>
        <mesh filename="package://amigo_description/media/meshes/forearmtextured.dae" scale="0.0004 0.0004 0.0004"/>
      </geometry>
      <material name="amigo_description/white"/>
    </visual>
    <collision>
      <origin rpy="0 -1.5708 0" xyz="0.00425 -0.14868 0.00547"/>
      <geometry>
        <mesh filename="package://amigo_description/media/meshes/forearmtextured.dae" scale="0.0004 0.0004 0.0004"/>
      </geometry>
    </collision>
  </link>
  <gazebo reference="fore_arm_right">
    <material>amigo_description/white</material>
    <turnGravityOff>false</turnGravityOff>
  </gazebo>
  <link name="wrist_link6_right">
    <inertial>
      <origin rpy="0 0 0" xyz="0.0 0.0 0.0"/>
      <mass value="0.01"/>
      <inertia ixx="0.001" ixy="0" ixz="0" iyy="0.03322" iyz="0" izz="0.001"/>
    </inertial>
    <visual>
      <origin rpy="1.5708 0 0" xyz="0.0 0.0 0.0"/>
      <geometry>
        <cylinder length="0.0" radius="0.0"/>
      </geometry>
      <material name="Black">
     </material>
    </visual>
    <collision>
      <origin rpy="1.5708 0 0" xyz="0.0 0.0 0.0"/>
      <geometry>
        <cylinder length="0.0" radius="0.0"/>
      </geometry>
    </collision>
  </link>
  <gazebo reference="wrist_link6_right">
    <material>Gazebo/Black</material>
    <turnGravityOff>false</turnGravityOff>
  </gazebo>
  <link name="hand_right">
    <inertial>
      <origin rpy="0 0 0" xyz="0.048 0.0 0.0"/>
      <mass value="0.2"/>
      <inertia ixx="0.01" ixy="0" ixz="0" iyy="0.01" iyz="0" izz="0.0622"/>
    </inertial>
    <visual>
      <origin rpy="0 0 0" xyz="0.048 0.0 0.0"/>
      <geometry>
        <box size="0.080 0.085 0.038"/>
      </geometry>
      <material name="Grey">
     </material>
    </visual>
    <collision>
      <origin rpy="0 0 0" xyz="0.048 0.0 0.0"/>
      <geometry>
        <box size="0.080 0.085 0.038"/>
      </geometry>
    </collision>
  </link>
  <gazebo reference="hand_right">
    <material>Gazebo/Grey</material>
    <turnGravityOff>false</turnGravityOff>
  </gazebo>
  <link name="finger1_right">
    <inertial>
      <origin rpy="0 0 0" xyz="0.0 0.0 -0.03"/>
      <mass value="0.01"/>
      <inertia ixx="0.01" ixy="0" ixz="0" iyy="0.01" iyz="0" izz="0.01"/>
    </inertial>
    <visual>
      <origin rpy="0 0 0" xyz="0.0 0.0 -0.03"/>
      <geometry>
        <box size="0.018 0.018 0.06"/>
      </geometry>
      <material name="Black">
     </material>
    </visual>
    <collision>
      <origin rpy="0 0 0" xyz="0.0 0.0 -0.03"/>
      <geometry>
        <box size="0.018 0.018 0.06"/>
      </geometry>
    </collision>
  </link>
  <gazebo reference="finger1_right">
    <material>Gazebo/Black</material>
    <turnGravityOff>false</turnGravityOff>
  </gazebo>
  <gazebo reference="finger1_right">
    <mu1 value="100.0"/>
    <mu2 value="100.0"/>
  </gazebo>
  <link name="finger1_phalanx_right">
    <inertial>
      <origin rpy="0 0 0" xyz="0.0 0.0 0"/>
      <mass value="0.01"/>
      <inertia ixx="0.001" ixy="0" ixz="0" iyy="0.001" iyz="0" izz="0.001"/>
    </inertial>
    <visual>
      <origin rpy="0 0 0" xyz="0.0 0.0 0"/>
      <geometry>
        <cylinder length="0.019" radius="0.009"/>
      </geometry>
      <material name="White">
     </material>
    </visual>
    <collision>
      <origin rpy="0 0 0" xyz="0.0 0.0 0"/>
      <geometry>
        <cylinder length="0.019" radius="0.009"/>
      </geometry>
    </collision>
  </link>
  <gazebo reference="finger1_phalanx_right">
    <material>Gazebo/White</material>
    <turnGravityOff>false</turnGravityOff>
  </gazebo>
  <link name="finger1_tip_right">
    <inertial>
      <origin rpy="0 0 0" xyz="0.0 0.0 -0.03"/>
      <mass value="0.01"/>
      <inertia ixx="0.00037" ixy="0" ixz="0" iyy="0.00052" iyz="0" izz="0.00052"/>
    </inertial>
    <visual>
      <origin rpy="0 0 0" xyz="0.0 0.0 -0.03"/>
      <geometry>
        <box size="0.018 0.018 0.06"/>
      </geometry>
      <material name="Black">
     </material>
    </visual>
    <collision>
      <origin rpy="0 0 0" xyz="0.0 0.0 -0.03"/>
      <geometry>
        <box size="0.018 0.018 0.06"/>
      </geometry>
    </collision>
  </link>
  <gazebo reference="finger1_tip_right">
    <material>Gazebo/Black</material>
    <turnGravityOff>false</turnGravityOff>
  </gazebo>
  <gazebo reference="finger1_tip_right">
    <mu1 value="100.0"/>
    <mu2 value="100.0"/>
  </gazebo>
  <link name="finger1_tip_phalanx_right">
    <inertial>
      <origin rpy="0 0 0" xyz="0.0 0.0 0"/>
      <mass value="0.01"/>
      <inertia ixx="0.001" ixy="0" ixz="0" iyy="0.001" iyz="0" izz="0.001"/>
    </inertial>
    <visual>
      <origin rpy="0 0 0" xyz="0.0 0.0 0"/>
      <geometry>
        <cylinder length="0.017" radius="0.009"/>
      </geometry>
      <material name="White">
     </material>
    </visual>
    <collision>
      <origin rpy="0 0 0" xyz="0.0 0.0 0"/>
      <geometry>
        <cylinder length="0.017" radius="0.009"/>
      </geometry>
    </collision>
  </link>
  <gazebo reference="finger1_tip_phalanx_right">
    <material>Gazebo/White</material>
    <turnGravityOff>false</turnGravityOff>
  </gazebo>
  <link name="finger2_right">
    <inertial>
      <origin rpy="0 0 0" xyz="0.0 0.0 -0.03"/>
      <mass value="0.01"/>
      <inertia ixx="0.01" ixy="0" ixz="0" iyy="0.01" iyz="0" izz="0.01"/>
    </inertial>
    <visual>
      <origin rpy="0 0 0" xyz="0.0 0.0 -0.03"/>
      <geometry>
        <box size="0.018 0.018 0.06"/>
      </geometry>
      <material name="Black">
     </material>
    </visual>
    <collision>
      <origin rpy="0 0 0" xyz="0.0 0.0 -0.03"/>
      <geometry>
        <box size="0.018 0.018 0.06"/>
      </geometry>
    </collision>
  </link>
  <gazebo reference="finger2_right">
    <material>Gazebo/Black</material>
    <turnGravityOff>false</turnGravityOff>
  </gazebo>
  <gazebo reference="finger2_right">
    <mu1 value="100.0"/>
    <mu2 value="100.0"/>
  </gazebo>
  <link name="finger2_phalanx_right">
    <inertial>
      <origin rpy="0 0 0" xyz="0.0 0.0 0"/>
      <mass value="0.01"/>
      <inertia ixx="0.001" ixy="0" ixz="0" iyy="0.001" iyz="0" izz="0.001"/>
    </inertial>
    <visual>
      <origin rpy="0 0 0" xyz="0.0 0.0 0"/>
      <geometry>
        <cylinder length="0.019" radius="0.009"/>
      </geometry>
      <material name="White">
     </material>
    </visual>
    <collision>
      <origin rpy="0 0 0" xyz="0.0 0.0 0"/>
      <geometry>
        <cylinder length="0.019" radius="0.009"/>
      </geometry>
    </collision>
  </link>
  <gazebo reference="finger2_phalanx_right">
    <material>Gazebo/White</material>
    <turnGravityOff>false</turnGravityOff>
  </gazebo>
  <link name="finger2_tip_right">
    <inertial>
      <origin rpy="0 0 0" xyz="0.0 0.0 -0.03"/>
      <mass value="0.01"/>
      <inertia ixx="0.00037" ixy="0" ixz="0" iyy="0.00052" iyz="0" izz="0.00052"/>
    </inertial>
    <visual>
      <origin rpy="0 0 0" xyz="0.0 0.0 -0.03"/>
      <geometry>
        <box size="0.018 0.018 0.06"/>
      </geometry>
      <material name="Black">
     </material>
    </visual>
    <collision>
      <origin rpy="0 0 0" xyz="0.0 0.0 -0.03"/>
      <geometry>
        <box size="0.018 0.018 0.06"/>
      </geometry>
    </collision>
  </link>
  <gazebo reference="finger2_tip_right">
    <material>Gazebo/Black</material>
    <turnGravityOff>false</turnGravityOff>
  </gazebo>
  <gazebo reference="finger2_tip_right">
    <mu1 value="100.0"/>
    <mu2 value="100.0"/>
  </gazebo>
  <link name="finger2_tip_phalanx_right">
    <inertial>
      <origin rpy="0 0 0" xyz="0.0 0.0 0"/>
      <mass value="0.01"/>
      <inertia ixx="0.001" ixy="0" ixz="0" iyy="0.001" iyz="0" izz="0.001"/>
    </inertial>
    <visual>
      <origin rpy="0 0 0" xyz="0.0 0.0 0"/>
      <geometry>
        <cylinder length="0.017" radius="0.009"/>
      </geometry>
      <material name="White">
     </material>
    </visual>
    <collision>
      <origin rpy="0 0 0" xyz="0.0 0.0 0"/>
      <geometry>
        <cylinder length="0.017" radius="0.009"/>
      </geometry>
    </collision>
  </link>
  <gazebo reference="finger2_tip_phalanx_right">
    <material>Gazebo/White</material>
    <turnGravityOff>false</turnGravityOff>
  </gazebo>
  <link name="grippoint_right">
    <inertial>
      <origin rpy="0 0 0" xyz="-0.1 0.0 0.0"/>
      <mass value="0.01"/>
      <inertia ixx="0.0001" ixy="0" ixz="0" iyy="0.0001" iyz="0" izz="0.0001"/>
    </inertial>
    <visual>
      <origin rpy="0 0 0 " xyz="-0.1 0.0 0.0"/>
      <geometry>
        <box size="0.0 0.0 0.0"/>
      </geometry>
      <material name="Blue">
     </material>
    </visual>
    <collision>
      <origin rpy="0 0 0 " xyz="-0.1 0.0 0.0"/>
      <geometry>
        <box size="0.0 0.0 0.0"/>
      </geometry>
    </collision>
  </link>
  <gazebo reference="grippoint_right">
    <material>Gazebo/Blue</material>
    <turnGravityOff>false</turnGravityOff>
  </gazebo>
  <joint name="shoulder_mount_joint_right" type="fixed">
    <parent link="trunk"/>
    <child link="shoulder_mount_right"/>
    <origin rpy="3.14 0 0.0" xyz="0.445 -0.22 0.0"/>
    <!-- Check length -->
  </joint>
  <joint name="shoulder_yaw_joint_right" type="revolute">
    <parent link="shoulder_mount_right"/>
    <child link="shoulder_link1_right"/>
    <origin rpy="-1.5708 -1.5708 0" xyz="0 0 0"/>
    <axis xyz="+1 0 0"/>
    <dynamics damping="4.0" friction="4.87"/>
    <limit effort="13.4" lower="-1.57" upper="0.0" velocity="1.0"/>
  </joint>
  <joint name="shoulder_pitch_joint_right" type="revolute">
    <parent link="shoulder_link1_right"/>
    <child link="shoulder_link2_right"/>
    <origin rpy="-1.5708  0 0" xyz="0.0 0.0 0.0"/>
    <axis xyz="0 -1 0"/>
    <dynamics damping="4.0" friction="6.06"/>
    <limit effort="13.4" lower="-1.57" upper="1.57" velocity="1.0"/>
  </joint>
  <joint name="shoulder_roll_joint_right" type="revolute">
    <parent link="shoulder_link2_right"/>
    <child link="upper_arm_right"/>
    <origin rpy="1.5708 0 0.0" xyz="0.0 0.0 0.0"/>
    <axis xyz="0 1.0 0"/>
    <dynamics damping="3.8" friction="2.216"/>
    <limit effort="9.8" lower="-1.57" upper="1.57" velocity="1.0"/>
  </joint>
  <joint name="elbow_pitch_joint_right" type="revolute">
    <parent link="upper_arm_right"/>
    <child link="elbow_link4_right"/>
    <origin rpy="-1.5708 0 0" xyz="0.01 -0.32 0.0"/>
    <axis xyz="0 -1 0"/>
    <dynamics damping="3" friction="1.18"/>
    <limit effort="4.5" lower="0.0" upper="2.23" velocity="1.0"/>
  </joint>
  <joint name="elbow_roll_joint_right" type="revolute">
    <parent link="elbow_link4_right"/>
    <child link="fore_arm_right"/>
    <origin rpy="1.5708 0 0" xyz="0.0 0.0 0.0"/>
    <axis xyz="0 1.0 0"/>
    <dynamics damping="3.5" friction="1.35"/>
    <limit effort="4.5" lower="-1.83" upper="1.83" velocity="1.0"/>
  </joint>
  <joint name="wrist_pitch_joint_right" type="revolute">
    <parent link="fore_arm_right"/>
    <child link="wrist_link6_right"/>
    <origin rpy="-1.5708 0 -1.5708" xyz="0.01 -0.28 0.0"/>
    <axis xyz="0 -1 0"/>
    <dynamics damping="0.35" friction="0.63"/>
    <limit effort="1" lower="-0.95" upper="0.95" velocity="1.0"/>
  </joint>
  <joint name="wrist_yaw_joint_right" type="revolute">
    <parent link="wrist_link6_right"/>
    <child link="hand_right"/>
    <origin rpy="0 0 0" xyz="0.0 0.0 0.0"/>
    <axis xyz="0 0 1.01"/>
    <dynamics damping="0.3" friction="0.68"/>
    <limit effort="1" lower="-0.61" upper="0.61" velocity="1.0"/>
  </joint>
  <joint name="finger1_joint_right" type="revolute">
    <parent link="hand_right"/>
    <child link="finger1_right"/>
    <origin rpy="0 -1.57 0" xyz=" 0.075 0.02 0"/>
    <axis xyz="1 0 0"/>
    <dynamics damping="0.5" friction="1.0"/>
    <limit effort="3" lower="-1.57" upper="1.57" velocity="1.0"/>
  </joint>
  <joint name="finger1_phalanx_joint_right" type="fixed">
    <parent link="finger1_right"/>
    <child link="finger1_phalanx_right"/>
    <origin rpy="0 1.57 0" xyz="0 0 -0.06"/>
  </joint>
  <joint name="finger1_tip_joint_right" type="revolute">
    <parent link="finger1_right"/>
    <child link="finger1_tip_right"/>
    <origin rpy="0 0 0" xyz=" 0 0.0 -0.06"/>
    <axis xyz="1 0 0"/>
    <dynamics damping="0.5" friction="1.0"/>
    <limit effort="3" lower="-1.57" upper="1.57" velocity="1.0"/>
  </joint>
  <joint name="finger1_tip_phalanx_joint_right" type="fixed">
    <parent link="finger1_tip_right"/>
    <child link="finger1_tip_phalanx_right"/>
    <origin rpy="0 1.57 0" xyz="0 0 -0.06"/>
  </joint>
  <joint name="finger2_joint_right" type="revolute">
    <parent link="hand_right"/>
    <child link="finger2_right"/>
    <origin rpy="0 -1.57 0" xyz="0.075 -0.02 0"/>
    <axis xyz="-1 0 0"/>
    <dynamics damping="0.5" friction="1.0"/>
    <limit effort="3" lower="-1.57" upper="1.57" velocity="1.0"/>
  </joint>
  <joint name="finger2_phalanx_joint_right" type="fixed">
    <parent link="finger2_right"/>
    <child link="finger2_phalanx_right"/>
    <origin rpy="0 1.57 0" xyz="0 0 -0.06"/>
  </joint>
  <joint name="finger2_tip_joint_right" type="revolute">
    <parent link="finger2_right"/>
    <child link="finger2_tip_right"/>
    <origin rpy="0 0 0" xyz="0 0 -0.06"/>
    <axis xyz="-1 0 0"/>
    <dynamics damping="0.5" friction="1.0"/>
    <limit effort="3" lower="-1.57" upper="1.57" velocity="1.0"/>
  </joint>
  <joint name="finger2_tip_phalanx_joint_right" type="fixed">
    <parent link="finger2_tip_right"/>
    <child link="finger2_tip_phalanx_right"/>
    <origin rpy="0 1.57 0" xyz="0 0 -0.06"/>
  </joint>
  <joint name="grippoint_joint_right" type="fixed">
    <parent link="hand_right"/>
    <child link="grippoint_right"/>
    <origin rpy="0 0 0" xyz="0.14 0.0 0.0"/>
  </joint>
  <link name="shoulder_mount_left">
    <inertial>
      <origin rpy="1.57 0 0" xyz="0.0 0.155 0.0"/>
      <mass value="0.15"/>
      <inertia ixx="0.01" ixy="0" ixz="0" iyy="0.01" iyz="0" izz="0.01"/>
    </inertial>
    <visual>
      <origin rpy="1.57 0 0 " xyz="0.0 0.155 0.0"/>
      <geometry>
        <cylinder length="0.140" radius="0.075"/>
      </geometry>
      <material name="White">
     </material>
    </visual>
    <collision>
      <origin rpy="1.57 0 0 " xyz="0.0 0.155 0.0"/>
      <geometry>
        <cylinder length="0.140" radius="0.075"/>
      </geometry>
    </collision>
  </link>
  <gazebo reference="shoulder_mount_left">
    <material>Gazebo/White</material>
    <turnGravityOff>false</turnGravityOff>
  </gazebo>
  <link name="shoulder_link1_left">
    <inertial>
      <origin rpy="0 0 0" xyz="0.0 0.0 0.0"/>
      <mass value="0.25"/>
      <inertia ixx="6.0" ixy="0" ixz="0" iyy="0.01" iyz="0" izz="0.01"/>
    </inertial>
    <visual>
      <origin rpy="0 0 0 " xyz="0.0 0.0 -0.0525"/>
      <geometry>
        <cylinder length="0.015" radius="0.045"/>
      </geometry>
      <material name="Black">
     </material>
    </visual>
    <collision>
      <origin rpy="0 0 0 " xyz="0.0 0.0 -0.0525"/>
      <geometry>
        <cylinder length="0.015" radius="0.045"/>
      </geometry>
    </collision>
  </link>
  <gazebo reference="shoulder_link1_left">
    <material>Gazebo/Black</material>
    <turnGravityOff>false</turnGravityOff>
  </gazebo>
  <link name="shoulder_link2_left">
    <inertial>
      <origin rpy="0 0 0" xyz="0.0 0.0 0.0"/>
      <mass value="0.15"/>
      <inertia ixx="0.01" ixy="0" ixz="0" iyy="4.04" iyz="0" izz="0.001"/>
    </inertial>
    <visual>
      <origin rpy="0 0 0" xyz="0.0 0.06 -0.05"/>
      <geometry>
        <box size="0.035 0.01 0.1"/>
      </geometry>
      <material name="Black">
     </material>
    </visual>
    <collision>
      <origin rpy="0 0 0" xyz="0.0 0.06 -0.05"/>
      <geometry>
        <box size="0.035 0.01 0.1"/>
      </geometry>
    </collision>
  </link>
  <gazebo reference="shoulder_link2_left">
    <material>Gazebo/Black</material>
    <turnGravityOff>false</turnGravityOff>
  </gazebo>
  <link name="upper_arm_left">
    <inertial>
      <origin rpy="0 0 0" xyz="0.0 -0.2 0.0"/>
      <mass value="2.95"/>
      <inertia ixx="0.027" ixy="0" ixz="0" iyy="0.45993" iyz="0" izz="0.004"/>
    </inertial>
    <visual>
      <origin rpy="0 0 3.1415" xyz="-0.00959 -0.19131 -0.00001"/>
      <geometry>
        <mesh filename="package://amigo_description/media/meshes/upperarmtextured.dae" scale="0.0004 0.0004 0.0004"/>
      </geometry>
      <material name="amigo_description/white"/>
    </visual>
    <collision>
      <origin rpy="0 0 3.1415" xyz="-0.00959 -0.19131 -0.00001"/>
      <geometry>
        <mesh filename="package://amigo_description/media/meshes/upperarmtextured.dae" scale="0.0004 0.0004 0.0004"/>
      </geometry>
    </collision>
  </link>
  <gazebo reference="upper_arm_left">
    <material>amigo_description/white</material>
    <turnGravityOff>false</turnGravityOff>
  </gazebo>
  <link name="elbow_link4_left">
    <inertial>
      <origin rpy="0 0 0" xyz="0.0 0.0 0.0"/>
      <mass value="0.1"/>
      <inertia ixx="0.001" ixy="0" ixz="0" iyy="0.6" iyz="0" izz="0.001"/>
    </inertial>
    <visual>
      <origin rpy="0 0 0" xyz="0.0 0.0 0.0"/>
      <geometry>
        <cylinder length="0.0" radius="0.0"/>
      </geometry>
      <material name="Grey">
     </material>
    </visual>
    <collision>
      <origin rpy="0 0 0" xyz="0.0 0.0 0.0"/>
      <geometry>
        <cylinder length="0.0" radius="0.0"/>
      </geometry>
    </collision>
  </link>
  <gazebo reference="elbow_link4_left">
    <material>Gazebo/Grey</material>
    <turnGravityOff>false</turnGravityOff>
  </gazebo>
  <link name="fore_arm_left">
    <inertial>
      <origin rpy="0.0 0 0" xyz="0.0 -0.14 0.0"/>
      <mass value="0.85"/>
      <inertia ixx="0.001" ixy="0" ixz="0" iyy="0.5" iyz="0" izz="0.001"/>
    </inertial>
    <visual>
      <origin rpy="0 -1.5708 0" xyz="0.00425 -0.14868 0.00547"/>
      <geometry>
        <mesh filename="package://amigo_description/media/meshes/forearmtextured.dae" scale="0.0004 0.0004 0.0004"/>
      </geometry>
      <material name="amigo_description/white"/>
    </visual>
    <collision>
      <origin rpy="0 -1.5708 0" xyz="0.00425 -0.14868 0.00547"/>
      <geometry>
        <mesh filename="package://amigo_description/media/meshes/forearmtextured.dae" scale="0.0004 0.0004 0.0004"/>
      </geometry>
    </collision>
  </link>
  <gazebo reference="fore_arm_left">
    <material>amigo_description/white</material>
    <turnGravityOff>false</turnGravityOff>
  </gazebo>
  <link name="wrist_link6_left">
    <inertial>
      <origin rpy="0 0 0" xyz="0.0 0.0 0.0"/>
      <mass value="0.01"/>
      <inertia ixx="0.001" ixy="0" ixz="0" iyy="0.03322" iyz="0" izz="0.001"/>
    </inertial>
    <visual>
      <origin rpy="1.5708 0 0" xyz="0.0 0.0 0.0"/>
      <geometry>
        <cylinder length="0.0" radius="0.0"/>
      </geometry>
      <material name="Black">
     </material>
    </visual>
    <collision>
      <origin rpy="1.5708 0 0" xyz="0.0 0.0 0.0"/>
      <geometry>
        <cylinder length="0.0" radius="0.0"/>
      </geometry>
    </collision>
  </link>
  <gazebo reference="wrist_link6_left">
    <material>Gazebo/Black</material>
    <turnGravityOff>false</turnGravityOff>
  </gazebo>
  <link name="hand_left">
    <inertial>
      <origin rpy="0 0 0" xyz="0.048 0.0 0.0"/>
      <mass value="0.2"/>
      <inertia ixx="0.01" ixy="0" ixz="0" iyy="0.01" iyz="0" izz="0.0622"/>
    </inertial>
    <visual>
      <origin rpy="0 0 0" xyz="0.048 0.0 0.0"/>
      <geometry>
        <box size="0.080 0.085 0.038"/>
      </geometry>
      <material name="Grey">
     </material>
    </visual>
    <collision>
      <origin rpy="0 0 0" xyz="0.048 0.0 0.0"/>
      <geometry>
        <box size="0.080 0.085 0.038"/>
      </geometry>
    </collision>
  </link>
  <gazebo reference="hand_left">
    <material>Gazebo/Grey</material>
    <turnGravityOff>false</turnGravityOff>
  </gazebo>
  <link name="finger1_left">
    <inertial>
      <origin rpy="0 0 0" xyz="0.0 0.0 -0.03"/>
      <mass value="0.01"/>
      <inertia ixx="0.01" ixy="0" ixz="0" iyy="0.01" iyz="0" izz="0.01"/>
    </inertial>
    <visual>
      <origin rpy="0 0 0" xyz="0.0 0.0 -0.03"/>
      <geometry>
        <box size="0.018 0.018 0.06"/>
      </geometry>
      <material name="Black">
     </material>
    </visual>
    <collision>
      <origin rpy="0 0 0" xyz="0.0 0.0 -0.03"/>
      <geometry>
        <box size="0.018 0.018 0.06"/>
      </geometry>
    </collision>
  </link>
  <gazebo reference="finger1_left">
    <material>Gazebo/Black</material>
    <turnGravityOff>false</turnGravityOff>
  </gazebo>
  <gazebo reference="finger1_left">
    <mu1 value="100.0"/>
    <mu2 value="100.0"/>
  </gazebo>
  <link name="finger1_phalanx_left">
    <inertial>
      <origin rpy="0 0 0" xyz="0.0 0.0 0"/>
      <mass value="0.01"/>
      <inertia ixx="0.001" ixy="0" ixz="0" iyy="0.001" iyz="0" izz="0.001"/>
    </inertial>
    <visual>
      <origin rpy="0 0 0" xyz="0.0 0.0 0"/>
      <geometry>
        <cylinder length="0.019" radius="0.009"/>
      </geometry>
      <material name="White">
     </material>
    </visual>
    <collision>
      <origin rpy="0 0 0" xyz="0.0 0.0 0"/>
      <geometry>
        <cylinder length="0.019" radius="0.009"/>
      </geometry>
    </collision>
  </link>
  <gazebo reference="finger1_phalanx_left">
    <material>Gazebo/White</material>
    <turnGravityOff>false</turnGravityOff>
  </gazebo>
  <link name="finger1_tip_left">
    <inertial>
      <origin rpy="0 0 0" xyz="0.0 0.0 -0.03"/>
      <mass value="0.01"/>
      <inertia ixx="0.00037" ixy="0" ixz="0" iyy="0.00052" iyz="0" izz="0.00052"/>
    </inertial>
    <visual>
      <origin rpy="0 0 0" xyz="0.0 0.0 -0.03"/>
      <geometry>
        <box size="0.018 0.018 0.06"/>
      </geometry>
      <material name="Black">
     </material>
    </visual>
    <collision>
      <origin rpy="0 0 0" xyz="0.0 0.0 -0.03"/>
      <geometry>
        <box size="0.018 0.018 0.06"/>
      </geometry>
    </collision>
  </link>
  <gazebo reference="finger1_tip_left">
    <material>Gazebo/Black</material>
    <turnGravityOff>false</turnGravityOff>
  </gazebo>
  <gazebo reference="finger1_tip_left">
    <mu1 value="100.0"/>
    <mu2 value="100.0"/>
  </gazebo>
  <link name="finger1_tip_phalanx_left">
    <inertial>
      <origin rpy="0 0 0" xyz="0.0 0.0 0"/>
      <mass value="0.01"/>
      <inertia ixx="0.001" ixy="0" ixz="0" iyy="0.001" iyz="0" izz="0.001"/>
    </inertial>
    <visual>
      <origin rpy="0 0 0" xyz="0.0 0.0 0"/>
      <geometry>
        <cylinder length="0.017" radius="0.009"/>
      </geometry>
      <material name="White">
     </material>
    </visual>
    <collision>
      <origin rpy="0 0 0" xyz="0.0 0.0 0"/>
      <geometry>
        <cylinder length="0.017" radius="0.009"/>
      </geometry>
    </collision>
  </link>
  <gazebo reference="finger1_tip_phalanx_left">
    <material>Gazebo/White</material>
    <turnGravityOff>false</turnGravityOff>
  </gazebo>
  <link name="finger2_left">
    <inertial>
      <origin rpy="0 0 0" xyz="0.0 0.0 -0.03"/>
      <mass value="0.01"/>
      <inertia ixx="0.01" ixy="0" ixz="0" iyy="0.01" iyz="0" izz="0.01"/>
    </inertial>
    <visual>
      <origin rpy="0 0 0" xyz="0.0 0.0 -0.03"/>
      <geometry>
        <box size="0.018 0.018 0.06"/>
      </geometry>
      <material name="Black">
     </material>
    </visual>
    <collision>
      <origin rpy="0 0 0" xyz="0.0 0.0 -0.03"/>
      <geometry>
        <box size="0.018 0.018 0.06"/>
      </geometry>
    </collision>
  </link>
  <gazebo reference="finger2_left">
    <material>Gazebo/Black</material>
    <turnGravityOff>false</turnGravityOff>
  </gazebo>
  <gazebo reference="finger2_left">
    <mu1 value="100.0"/>
    <mu2 value="100.0"/>
  </gazebo>
  <link name="finger2_phalanx_left">
    <inertial>
      <origin rpy="0 0 0" xyz="0.0 0.0 0"/>
      <mass value="0.01"/>
      <inertia ixx="0.001" ixy="0" ixz="0" iyy="0.001" iyz="0" izz="0.001"/>
    </inertial>
    <visual>
      <origin rpy="0 0 0" xyz="0.0 0.0 0"/>
      <geometry>
        <cylinder length="0.019" radius="0.009"/>
      </geometry>
      <material name="White">
     </material>
    </visual>
    <collision>
      <origin rpy="0 0 0" xyz="0.0 0.0 0"/>
      <geometry>
        <cylinder length="0.019" radius="0.009"/>
      </geometry>
    </collision>
  </link>
  <gazebo reference="finger2_phalanx_left">
    <material>Gazebo/White</material>
    <turnGravityOff>false</turnGravityOff>
  </gazebo>
  <link name="finger2_tip_left">
    <inertial>
      <origin rpy="0 0 0" xyz="0.0 0.0 -0.03"/>
      <mass value="0.01"/>
      <inertia ixx="0.00037" ixy="0" ixz="0" iyy="0.00052" iyz="0" izz="0.00052"/>
    </inertial>
    <visual>
      <origin rpy="0 0 0" xyz="0.0 0.0 -0.03"/>
      <geometry>
        <box size="0.018 0.018 0.06"/>
      </geometry>
      <material name="Black">
     </material>
    </visual>
    <collision>
      <origin rpy="0 0 0" xyz="0.0 0.0 -0.03"/>
      <geometry>
        <box size="0.018 0.018 0.06"/>
      </geometry>
    </collision>
  </link>
  <gazebo reference="finger2_tip_left">
    <material>Gazebo/Black</material>
    <turnGravityOff>false</turnGravityOff>
  </gazebo>
  <gazebo reference="finger2_tip_left">
    <mu1 value="100.0"/>
    <mu2 value="100.0"/>
  </gazebo>
  <link name="finger2_tip_phalanx_left">
    <inertial>
      <origin rpy="0 0 0" xyz="0.0 0.0 0"/>
      <mass value="0.01"/>
      <inertia ixx="0.001" ixy="0" ixz="0" iyy="0.001" iyz="0" izz="0.001"/>
    </inertial>
    <visual>
      <origin rpy="0 0 0" xyz="0.0 0.0 0"/>
      <geometry>
        <cylinder length="0.017" radius="0.009"/>
      </geometry>
      <material name="White">
     </material>
    </visual>
    <collision>
      <origin rpy="0 0 0" xyz="0.0 0.0 0"/>
      <geometry>
        <cylinder length="0.017" radius="0.009"/>
      </geometry>
    </collision>
  </link>
  <gazebo reference="finger2_tip_phalanx_left">
    <material>Gazebo/White</material>
    <turnGravityOff>false</turnGravityOff>
  </gazebo>
  <link name="grippoint_left">
    <inertial>
      <origin rpy="0 0 0" xyz="-0.1 0.0 0.0"/>
      <mass value="0.01"/>
      <inertia ixx="0.0001" ixy="0" ixz="0" iyy="0.0001" iyz="0" izz="0.0001"/>
    </inertial>
    <visual>
      <origin rpy="0 0 0 " xyz="-0.1 0.0 0.0"/>
      <geometry>
        <box size="0.0 0.0 0.0"/>
      </geometry>
      <material name="Blue">
     </material>
    </visual>
    <collision>
      <origin rpy="0 0 0 " xyz="-0.1 0.0 0.0"/>
      <geometry>
        <box size="0.0 0.0 0.0"/>
      </geometry>
    </collision>
  </link>
  <gazebo reference="grippoint_left">
    <material>Gazebo/Blue</material>
    <turnGravityOff>false</turnGravityOff>
  </gazebo>
  <joint name="shoulder_mount_joint_left" type="fixed">
    <parent link="trunk"/>
    <child link="shoulder_mount_left"/>
    <origin rpy="3.14 0 0.0" xyz="0.445 0.22 0.0"/>
    <!-- Check length -->
  </joint>
  <joint name="shoulder_yaw_joint_left" type="revolute">
    <parent link="shoulder_mount_left"/>
    <child link="shoulder_link1_left"/>
    <origin rpy="-1.5708 -1.5708 0" xyz="0 0 0"/>
    <axis xyz="-1 0 0"/>
    <dynamics damping="4.0" friction="4.87"/>
    <limit effort="13.4" lower="-1.57" upper="0.0" velocity="1.0"/>
  </joint>
  <joint name="shoulder_pitch_joint_left" type="revolute">
    <parent link="shoulder_link1_left"/>
    <child link="shoulder_link2_left"/>
    <origin rpy="-1.5708  0 0" xyz="0.0 0.0 0.0"/>
    <axis xyz="0 -1 0"/>
    <dynamics damping="4.0" friction="6.06"/>
    <limit effort="13.4" lower="-1.57" upper="1.57" velocity="1.0"/>
  </joint>
  <joint name="shoulder_roll_joint_left" type="revolute">
    <parent link="shoulder_link2_left"/>
    <child link="upper_arm_left"/>
    <origin rpy="1.5708 0 0.0" xyz="0.0 0.0 0.0"/>
    <axis xyz="0 -1.0 0"/>
    <dynamics damping="3.8" friction="2.216"/>
    <limit effort="9.8" lower="-1.57" upper="1.57" velocity="1.0"/>
  </joint>
  <joint name="elbow_pitch_joint_left" type="revolute">
    <parent link="upper_arm_left"/>
    <child link="elbow_link4_left"/>
    <origin rpy="-1.5708 0 0" xyz="0.01 -0.32 0.0"/>
    <axis xyz="0 -1 0"/>
    <dynamics damping="3" friction="1.18"/>
    <limit effort="4.5" lower="0.0" upper="2.23" velocity="1.0"/>
  </joint>
  <joint name="elbow_roll_joint_left" type="revolute">
    <parent link="elbow_link4_left"/>
    <child link="fore_arm_left"/>
    <origin rpy="1.5708 0 0" xyz="0.0 0.0 0.0"/>
    <axis xyz="0 -1.0 0"/>
    <dynamics damping="3.5" friction="1.35"/>
    <limit effort="4.5" lower="-1.83" upper="1.83" velocity="1.0"/>
  </joint>
  <joint name="wrist_pitch_joint_left" type="revolute">
    <parent link="fore_arm_left"/>
    <child link="wrist_link6_left"/>
    <origin rpy="-1.5708 0 -1.5708" xyz="0.01 -0.28 0.0"/>
    <axis xyz="0 -1 0"/>
    <dynamics damping="0.35" friction="0.63"/>
    <limit effort="1" lower="-0.95" upper="0.95" velocity="1.0"/>
  </joint>
  <joint name="wrist_yaw_joint_left" type="revolute">
    <parent link="wrist_link6_left"/>
    <child link="hand_left"/>
    <origin rpy="0 0 0" xyz="0.0 0.0 0.0"/>
    <axis xyz="0 0 -1.01"/>
    <dynamics damping="0.3" friction="0.68"/>
    <limit effort="1" lower="-0.61" upper="0.61" velocity="1.0"/>
  </joint>
  <joint name="finger1_joint_left" type="revolute">
    <parent link="hand_left"/>
    <child link="finger1_left"/>
    <origin rpy="0 -1.57 0" xyz=" 0.075 0.02 0"/>
    <axis xyz="1 0 0"/>
    <dynamics damping="0.5" friction="1.0"/>
    <limit effort="3" lower="-1.57" upper="1.57" velocity="1.0"/>
  </joint>
  <joint name="finger1_phalanx_joint_left" type="fixed">
    <parent link="finger1_left"/>
    <child link="finger1_phalanx_left"/>
    <origin rpy="0 1.57 0" xyz="0 0 -0.06"/>
  </joint>
  <joint name="finger1_tip_joint_left" type="revolute">
    <parent link="finger1_left"/>
    <child link="finger1_tip_left"/>
    <origin rpy="0 0 0" xyz=" 0 0.0 -0.06"/>
    <axis xyz="1 0 0"/>
    <dynamics damping="0.5" friction="1.0"/>
    <limit effort="3" lower="-1.57" upper="1.57" velocity="1.0"/>
  </joint>
  <joint name="finger1_tip_phalanx_joint_left" type="fixed">
    <parent link="finger1_tip_left"/>
    <child link="finger1_tip_phalanx_left"/>
    <origin rpy="0 1.57 0" xyz="0 0 -0.06"/>
  </joint>
  <joint name="finger2_joint_left" type="revolute">
    <parent link="hand_left"/>
    <child link="finger2_left"/>
    <origin rpy="0 -1.57 0" xyz="0.075 -0.02 0"/>
    <axis xyz="-1 0 0"/>
    <dynamics damping="0.5" friction="1.0"/>
    <limit effort="3" lower="-1.57" upper="1.57" velocity="1.0"/>
  </joint>
  <joint name="finger2_phalanx_joint_left" type="fixed">
    <parent link="finger2_left"/>
    <child link="finger2_phalanx_left"/>
    <origin rpy="0 1.57 0" xyz="0 0 -0.06"/>
  </joint>
  <joint name="finger2_tip_joint_left" type="revolute">
    <parent link="finger2_left"/>
    <child link="finger2_tip_left"/>
    <origin rpy="0 0 0" xyz="0 0 -0.06"/>
    <axis xyz="-1 0 0"/>
    <dynamics damping="0.5" friction="1.0"/>
    <limit effort="3" lower="-1.57" upper="1.57" velocity="1.0"/>
  </joint>
  <joint name="finger2_tip_phalanx_joint_left" type="fixed">
    <parent link="finger2_tip_left"/>
    <child link="finger2_tip_phalanx_left"/>
    <origin rpy="0 1.57 0" xyz="0 0 -0.06"/>
  </joint>
  <joint name="grippoint_joint_left" type="fixed">
    <parent link="hand_left"/>
    <child link="grippoint_left"/>
    <origin rpy="0 0 0" xyz="0.14 0.0 0.0"/>
  </joint>
  <!--========BUILD HEAD======-->
  <author>Kris van Tienhoven, Janno Lunenburg</author>
  <license>BSD</license>
  <review notes="" status="unreviewed"/>
  <link name="head_mount">
    <inertial>
      <origin rpy="0 0 0" xyz="0.0 0.0 0.0"/>
      <mass value="0.001"/>
      <inertia ixx="0.0001" ixy="0" ixz="0" iyy="0.0001" iyz="0" izz="0.0001"/>
    </inertial>
  </link>
  <joint name="head_mount_joint" type="fixed">
    <parent link="trunk"/>
    <child link="head_mount"/>
    <axis xyz="0 0 1"/>
    <origin rpy="3.14 0.0 0.0" xyz="0.5 0.0 0.0"/>
    <!-- Check length -->
  </joint>
  <link name="neck_pan">
    <inertial>
      <origin rpy="0 0 0" xyz="0.0 0.0 0.0335"/>
      <mass value="0.05"/>
      <inertia ixx="0.0001" ixy="0" ixz="0" iyy="0.0001" iyz="0" izz="0.0001"/>
    </inertial>
    <visual>
      <origin rpy="0 0 0" xyz="0.0 0.0 0.0335"/>
      <geometry>
        <cylinder length="0.0525" radius="0.015"/>
      </geometry>
      <material name="White">
     </material>
    </visual>
    <collision>
      <origin rpy="0 0 0" xyz="0.0 0.0 0.0335"/>
      <geometry>
        <cylinder length="0.0525" radius="0.015"/>
      </geometry>
    </collision>
  </link>
  <gazebo reference="neck_pan">
    <material>Gazebo/White</material>
    <turnGravityOff>false</turnGravityOff>
  </gazebo>
  <link name="neck_tilt">
    <inertial>
      <origin rpy="0 0 0" xyz="0.0 -0.0 0.0285"/>
      <mass value="0.05"/>
      <inertia ixx="0.001" ixy="0" ixz="0" iyy="0.001" iyz="0" izz="0.001"/>
    </inertial>
    <visual>
      <origin rpy="0 0 0" xyz="0.0 -0.0 0.015"/>
      <geometry>
        <box size="0.001 0.001 0.001"/>
      </geometry>
      <material name="White">
     </material>
    </visual>
    <collision>
      <origin rpy="0 0 0" xyz="0.0 -0.0 0.015"/>
      <geometry>
        <box size="0.001 0.001 0.001"/>
      </geometry>
    </collision>
  </link>
  <gazebo reference="neck_tilt">
    <material>Gazebo/White</material>
    <turnGravityOff>false</turnGravityOff>
  </gazebo>
  <link name="head">
    <inertial>
      <origin rpy="0 0 0" xyz="0 0 0.041"/>
      <mass value="0"/>
      <inertia ixx="0" ixy="0" ixz="0" iyy="0" iyz="0" izz="0"/>
    </inertial>
    <visual>
      <origin rpy="0 0 -1.5708" xyz="0.0 0.0 0.141"/>
      <geometry>
        <box size="0.001 0.001 0.001"/>
      </geometry>
      <material name="White">
     </material>
    </visual>
    <collision>
      <origin rpy="0 0 -1.5708" xyz="0.0 0.0 0.141"/>
      <geometry>
        <box size="0.001 0.001 0.001"/>
      </geometry>
    </collision>
  </link>
  <gazebo reference="head">
    <material>Gazebo/White</material>
    <turnGravityOff>false</turnGravityOff>
  </gazebo>
  <joint name="head_joint" type="fixed">
    <parent link="neck_tilt"/>
    <child link="head"/>
  </joint>
  <joint name="neck_pan_joint" type="revolute">
    <parent link="head_mount"/>
    <child link="neck_pan"/>
    <origin rpy="3.14 -1.5708 0.0" xyz="0.0 0.0 0.0"/>
    <axis xyz="0 0 1"/>
    <dynamics damping="0.1" friction="0"/>
    <limit effort="13.4" lower="-1.5708" upper="1.5708" velocity="1.0"/>
  </joint>
  <joint name="neck_tilt_joint" type="revolute">
    <parent link="neck_pan"/>
    <child link="neck_tilt"/>
    <origin rpy="0.0 0.0 0.0" xyz="0.0 0.0 0.0445"/>
    <axis xyz="0 1 0"/>
    <dynamics damping="0.1" friction="0.0"/>
    <limit effort="13.4" lower="-2.0" upper="2.0" velocity="1.0"/>
  </joint>
  <!--========BUILD KINECT======-->
  <joint name="top_kinect/base_kinect_joint" type="fixed">
    <origin rpy="0 0 0" xyz="0.07 0 0.07"/>
    <!-- THESE VALUES ARE ROUGH ESTIMATES!! -->
    <parent link="head"/>
    <child link="top_kinect/openni_camera"/>
  </joint>
  <link name="top_kinect/openni_camera">
    <inertial>
      <mass value="0.01"/>
      <origin xyz="0 0 0"/>
      <inertia ixx="0.001" ixy="0.0" ixz="0.0" iyy="0.001" iyz="0.0" izz="0.001"/>
    </inertial>
    <visual>
      <origin rpy="0 0 0" xyz=" 0 0 0 "/>
      <geometry>
        <!--<box size="0.001 0.001 0.001"/>-->
        <!--Changed to 0.001 because otherwise it doesn't work-->
        <!--mesh filename="package://amigo_description/kinect/meshes/kinect.dae" scale="0.001 0.001 0.001"/-->
        <mesh filename="package://amigo2_description/media/meshes/kinect_without_base.dae"/>
      </geometry>
    </visual>
    <!--<collision>
      <origin xyz="-0.0365 0.0 0.0" rpy="0 0 0" />
      <geometry>
        <box size="0.0730 .2760 0.0720"/>
      </geometry>
    </collision>-->
  </link>
  <joint name="top_kinect/kinect_depth_joint" type="fixed">
    <origin rpy="0 0 0" xyz="0 0.018 0"/>
    <parent link="top_kinect/openni_camera"/>
    <child link="top_kinect/openni_depth_frame"/>
  </joint>
  <link name="top_kinect/openni_depth_frame">
    <inertial>
      <mass value="0.01"/>
      <origin xyz="0 0 0"/>
      <inertia ixx="0.001" ixy="0.0" ixz="0.0" iyy="0.001" iyz="0.0" izz="0.001"/>
    </inertial>
  </link>
  <joint name="top_kinect/kinect_depth_optical_joint" type="fixed">
    <origin rpy="-1.570795 0 -1.570795" xyz="0 0 0"/>
    <parent link="top_kinect/openni_depth_frame"/>
    <child link="top_kinect/openni_depth_optical_frame"/>
  </joint>
  <link name="top_kinect/openni_depth_optical_frame">
    <inertial>
      <mass value="0.001"/>
      <origin xyz="0 0 0"/>
      <inertia ixx="0.0001" ixy="0.0" ixz="0.0" iyy="0.0001" iyz="0.0" izz="0.0001"/>
    </inertial>
  </link>
  <joint name="top_kinect/kinect_rgb_joint" type="fixed">
    <origin rpy="0 0 0" xyz="0 -0.005 0"/>
    <parent link="top_kinect/openni_camera"/>
    <child link="top_kinect/openni_rgb_frame"/>
  </joint>
  <link name="top_kinect/openni_rgb_frame">
    <inertial>
      <mass value="0.001"/>
      <origin xyz="0 0 0"/>
      <inertia ixx="0.0001" ixy="0.0" ixz="0.0" iyy="0.0001" iyz="0.0" izz="0.0001"/>
    </inertial>
  </link>
  <joint name="top_kinect/kinect_rgb_optical_joint" type="fixed">
    <origin rpy="-1.570795 0 -1.570795" xyz="0 0 0"/>
    <parent link="top_kinect/openni_rgb_frame"/>
    <child link="top_kinect/openni_rgb_optical_frame"/>
  </joint>
  <link name="top_kinect/openni_rgb_optical_frame">
    <inertial>
      <mass value="0.001"/>
      <origin xyz="0 0 0"/>
      <inertia ixx="0.0001" ixy="0.0" ixz="0.0" iyy="0.0001" iyz="0.0" izz="0.0001"/>
    </inertial>
  </link>
  <!--========BUILD LASER======-->
  <author>Kris van Tienhoven</author>
  <license>BSD</license>
  <review notes="" status="unreviewed"/>
  <link name="base_laser">
    <inertial>
      <origin rpy="0 0 0" xyz="0.0 0.0 0.0"/>
      <mass value="0.5"/>
      <inertia ixx="0.0001" ixy="0" ixz="0" iyy="0.0001" iyz="0" izz="0.0001"/>
    </inertial>
    <visual>
      <origin rpy="0 0 0" xyz="-0.005 0.0 -0.065"/>
      <geometry>
        <box size="0.05 0.065 0.12"/>
      </geometry>
      <material name="Black">
     </material>
    </visual>
    <collision>
      <origin rpy="0 0 0" xyz="-0.005 0.0 -0.065"/>
      <geometry>
        <box size="0.05 0.065 0.12"/>
      </geometry>
    </collision>
  </link>
  <gazebo reference="base_laser">
    <material>Gazebo/Black</material>
    <turnGravityOff>false</turnGravityOff>
  </gazebo>
  <joint name="base_laser_joint" type="fixed">
    <parent link="base"/>
    <child link="base_laser"/>
    <origin rpy="3.14 0 0" xyz="0.35 0.0 -0.06"/>
    <axis xyz="0 1 0"/>
    <dynamics damping="0.1" friction="0"/>
    <limit effort="13.4" lower="-0.7809" upper="1.5708" velocity="1.0"/>
  </joint>
  <link name="lasertop">
    <inertial>
      <origin rpy="0 0 0" xyz="0.0 0.0 0.0"/>
      <mass value="0.01"/>
      <inertia ixx="0.0001" ixy="0" ixz="0" iyy="0.0001" iyz="0" izz="0.0001"/>
    </inertial>
    <visual>
      <origin rpy="0 0 0" xyz="-0.005 0.0 0.0"/>
      <geometry>
        <box size="0.05 0.065 0.01"/>
      </geometry>
      <material name="Red">
     </material>
    </visual>
    <collision>
      <origin rpy="0 0 0" xyz="-0.005 0.0 0.0"/>
      <geometry>
        <box size="0.05 0.065 0.01"/>
      </geometry>
    </collision>
  </link>
  <gazebo reference="lasertop">
    <material>Gazebo/Red</material>
    <turnGravityOff>false</turnGravityOff>
  </gazebo>
  <joint name="lasertop_joint" type="fixed">
    <parent link="base_laser"/>
    <child link="lasertop"/>
  </joint>
  <author>Kris van Tienhoven</author>
  <license>BSD</license>
  <review notes="" status="unreviewed"/>
  <link name="torso_laser">
    <inertial>
      <origin rpy="0 0 0" xyz="0.0 0.0 0.0"/>
      <mass value="0.5"/>
      <inertia ixx="0.0001" ixy="0" ixz="0" iyy="0.0001" iyz="0" izz="0.0001"/>
    </inertial>
    <visual>
      <origin rpy="0 0 0" xyz="-0.005 0.0 -0.065"/>
      <geometry>
        <box size="0.05 0.065 0.12"/>
      </geometry>
      <material name="Black">
     </material>
    </visual>
    <collision>
      <origin rpy="0 0 0" xyz="-0.005 0.0 -0.065"/>
      <geometry>
        <box size="0.05 0.065 0.12"/>
      </geometry>
    </collision>
  </link>
  <gazebo reference="torso_laser">
    <material>Gazebo/Black</material>
    <turnGravityOff>false</turnGravityOff>
  </gazebo>
  <joint name="torso_laser_joint" type="revolute">
    <parent link="trunk"/>
    <child link="torso_laser"/>
    <origin rpy="3.14 1.57 0.0 " xyz="0.22 0.0 -0.1"/>
    <axis xyz="0 1 0"/>
    <dynamics damping="0.1" friction="0"/>
    <limit effort="13.4" lower="-0.7809" upper="1.5708" velocity="1.0"/>
  </joint>
  <link name="torso_lasertop">
    <inertial>
      <origin rpy="0 0 0" xyz="0.0 0.0 0.0"/>
      <mass value="0.01"/>
      <inertia ixx="0.0001" ixy="0" ixz="0" iyy="0.0001" iyz="0" izz="0.0001"/>
    </inertial>
    <visual>
      <origin rpy="0 0 0" xyz="-0.005 0.0 0.0"/>
      <geometry>
        <box size="0.05 0.065 0.01"/>
      </geometry>
      <material name="Red">
     </material>
    </visual>
    <collision>
      <origin rpy="0 0 0" xyz="-0.005 0.0 0.0"/>
      <geometry>
        <box size="0.05 0.065 0.01"/>
      </geometry>
    </collision>
  </link>
  <gazebo reference="torso_lasertop">
    <material>Gazebo/Red</material>
    <turnGravityOff>false</turnGravityOff>
  </gazebo>
  <joint name="torso_lasertop_joint" type="fixed">
    <parent link="torso_laser"/>
    <child link="torso_lasertop"/>
  </joint>
  <!-- GAZEBO -->
  <gazebo>
    <link name="base_fixed_link">
      <pose>0.000000 0.000000 0.000000 0.000000 0.000000 0.000000</pose>
      <inertial>
        <pose>0.000000 0.000000 0.000000 0.000000 0.000000 0.000000</pose>
        <mass>10.000000</mass>
        <inertia>
          <ixx>0.100000</ixx>
          <ixy>0.100000</ixy>
          <ixz>0.100000</ixz>
          <iyy>0.100000</iyy>
          <iyz>0.100000</iyz>
          <izz>0.100000</izz>
        </inertia>
      </inertial>
      <velocity_decay>
        <linear>0.000000</linear>
        <angular>0.000000</angular>
      </velocity_decay>
    </link>
    <joint name="base_fixed_joint" type="revolute">
      <child>base_fixed_link</child>
      <parent>world</parent>
      <axis>
        <limit>
          <lower>0.000000</lower>
          <upper>0.000000</upper>
        </limit>
        <dynamics>
          <damping>0.000000</damping>
        </dynamics>
        <xyz>0.000000 0.000000 1.000000</xyz>
      </axis>
    </joint>
    <link name="base_x_link">
      <pose>0.000000 0.000000 0.000000 0.000000 0.000000 0.000000</pose>
      <inertial>
        <pose>0.000000 0.000000 0.000000 0.000000 0.000000 0.000000</pose>
        <mass>10.000000</mass>
        <inertia>
          <ixx>0.100000</ixx>
          <ixy>0.100000</ixy>
          <ixz>0.100000</ixz>
          <iyy>0.100000</iyy>
          <iyz>0.100000</iyz>
          <izz>0.100000</izz>
        </inertia>
      </inertial>
      <velocity_decay>
        <linear>0.000000</linear>
        <angular>0.000000</angular>
      </velocity_decay>
    </link>
    <joint name="base_x_joint" type="prismatic">
      <child>base_x_link</child>
      <parent>base_fixed_link</parent>
      <axis>
        <xyz>1.000000 0.000000 0.000000</xyz>
        <limit>
          <lower>-1000.000000</lower>
          <upper>1000.000000</upper>
        </limit>
        <dynamics>
          <damping>100.000000</damping>
        </dynamics>
      </axis>
    </joint>
    <link name="base_y_link">
      <pose>0.000000 0.000000 0.000000 0.000000 0.000000 0.000000</pose>
      <inertial>
        <pose>0.000000 0.000000 0.000000 0.000000 0.000000 0.000000</pose>
        <mass>10.000000</mass>
        <inertia>
          <ixx>0.100000</ixx>
          <ixy>0.100000</ixy>
          <ixz>0.100000</ixz>
          <iyy>0.100000</iyy>
          <iyz>0.100000</iyz>
          <izz>0.100000</izz>
        </inertia>
      </inertial>
      <velocity_decay>
        <linear>0.000000</linear>
        <angular>0.000000</angular>
      </velocity_decay>
    </link>
    <joint name="base_y_joint" type="prismatic">
      <child>base_y_link</child>
      <parent>base_x_link</parent>
      <axis>
        <xyz>0.000000 1.000000 0.000000</xyz>
        <limit>
          <lower>-1000.000000</lower>
          <upper>1000.000000</upper>
        </limit>
        <dynamics>
          <damping>100.000000</damping>
        </dynamics>
      </axis>
    </joint>
    <joint name="base_phi_joint" type="revolute">
      <child>base_link</child>
      <parent>base_y_link</parent>
      <axis>
        <xyz>0.000000 0.000000 1.000000</xyz>
        <limit>
          <lower>-10000000000000000.000000</lower>
          <upper>10000000000000000.000000</upper>
        </limit>
        <dynamics>
          <damping>100.000000</damping>
        </dynamics>
      </axis>
    </joint>
  </gazebo>
  <gazebo reference="base_link">
    <sensor name="base_kinect_openni_camera" type="depth">
      <update_rate>20.000000</update_rate>
      <camera name="base_kinect">
        <horizontal_fov>1.047198</horizontal_fov>
        <image>
          <width>640</width>
          <height>480</height>
          <format>R8G8B8</format>
        </image>
        <clip>
          <near>0.050000</near>
          <far>3.000000</far>
        </clip>
      </camera>
      <plugin filename="libKinectPlugin.so" name="base_kinect_camera_controller">
        <alwaysOn>1</alwaysOn>
        <updateRate>20</updateRate>
        <cameraName>base_kinect</cameraName>
        <imageTopicName>rgb/image_color</imageTopicName>
        <cameraInfoTopicName>rgb/camera_info</cameraInfoTopicName>
        <depthImageTopicName>depth/image</depthImageTopicName>
        <depthImageCameraInfoTopicName>depth/camera_info</depthImageCameraInfoTopicName>
        <pointCloudTopicName>rgb/points</pointCloudTopicName>
        <frameName>base_kinect/openni_depth_optical_frame</frameName>
      </plugin>
      <pose>0.300000 0.000000 0.315000 0.000000 -0.070000 0.000000</pose>
    </sensor>
    <sensor name="base_ray_sensor" type="ray">
      <update_rate>100.000000</update_rate>
      <ray>
        <scan>
          <horizontal>
            <samples>918</samples>
            <resolution>1.000000</resolution>
            <min_angle>-2.0027654171</min_angle>
            <max_angle>1.99840199947</max_angle>
          </horizontal>
          <vertical>
            <samples>1</samples>
            <min_angle>0.000000</min_angle>
            <max_angle>0.000000</max_angle>
          </vertical>
        </scan>
        <range>
          <min>0.05</min>
          <max>60.0</max>
          <resolution>0.010000</resolution>
        </range>
      </ray>
      <plugin filename="libLaserPlugin.so" name="base_ros_ray_sensor_controller">
        <gaussianNoise>0.005</gaussianNoise>
        <alwaysOn>1</alwaysOn>
        <updateRate>40</updateRate>
        <topicName>base_front_laser</topicName>
        <node_namespace>base</node_namespace>
        <frameName>base_laser</frameName>
      </plugin>
      <pose>0.310000 0.000000 0.240000 0.000000 0.000000 0.000000</pose>
    </sensor>
  </gazebo>
  <gazebo reference="neck_tilt">
    <sensor name="openni_camera" type="depth">
      <update_rate>20.000000</update_rate>
      <camera name="top_kinect">
        <horizontal_fov>1.047198</horizontal_fov>
        <image>
          <width>640</width>
          <height>480</height>
          <format>R8G8B8</format>
        </image>
        <clip>
          <near>0.050000</near>
          <far>3.000000</far>
        </clip>
      </camera>
      <plugin filename="libKinectPlugin.so" name="kinect_camera_controller">
        <alwaysOn>1</alwaysOn>
        <updateRate>20</updateRate>
        <cameraName>top_kinect</cameraName>
        <imageTopicName>rgb/image_color</imageTopicName>
        <cameraInfoTopicName>rgb/camera_info</cameraInfoTopicName>
        <depthImageTopicName>depth/image</depthImageTopicName>
        <depthImageCameraInfoTopicName>depth/camera_info</depthImageCameraInfoTopicName>
        <pointCloudTopicName>rgb/points</pointCloudTopicName>
        <frameName>top_kinect/openni_depth_optical_frame</frameName>
      </plugin>
      <pose>0.070000 0.000000 0.070000 0.000000 0.000000 0.000000</pose>
    </sensor>
  </gazebo>
  <gazebo>
    <plugin filename="libPositionController.so" name="position_controller">
      <package>amigo2_description</package>
      <group_summary_file>custom/joint_groups.yaml</group_summary_file>
    </plugin>
    <plugin filename="libAmigoBaseController.so" name="base_controller">
      <package>amigo2_controller_configuration_gazebo</package>
      <parameter_file>/parameters/mod_base_controller.yaml</parameter_file>
      <node_namespace>base</node_namespace>
      <odomTopic>odom</odomTopic>
    </plugin>
  </gazebo>
</robot>
