<?xml version="1.0" ?>
<!-- =================================================================================== -->
<!-- |    This document was autogenerated by xacro from /home/amigo/ros/kinetic/system/src/sergio_description/urdf/sergio.urdf.xacro | -->
<!-- |    EDITING THIS FILE BY HAND IS NOT RECOMMENDED                                 | -->
<!-- =================================================================================== -->
<robot name="sergio" xmlns:xacro="http://ros.org/wiki/xacro">
  <author>Janno Lunenburg</author>
  <license>BSD</license>
  <review notes="" status="unreviewed"/>
  <!-- ToDo: In general: look at DH conventions-->
  <!-- *************** LINK Definitions *****************-->
  <author>Kris van Tienhoven</author>
  <license>BSD</license>
  <review notes="" status="unreviewed"/>
  <author>Kris van Tienhoven</author>
  <license>BSD</license>
  <review notes="" status="unreviewed"/>
  <!-- this files contains the definitions for all colors and textures for rviz -->
  <material name="Blue">
    <color rgba="0.0 0.0 0.8 1.0"/>
  </material>
  <material name="Green">
    <color rgba="0.0 0.8 0.0 1.0"/>
  </material>
  <material name="Grey">
    <color rgba="0.7 0.7 0.7 1.0"/>
  </material>
  <material name="Grey2">
    <color rgba="0.9 0.9 0.9 1.0"/>
  </material>
  <material name="Red">
    <color rgba="0.8 0.0 0.0 1.0"/>
  </material>
  <material name="White">
    <color rgba="1.0 1.0 1.0 1.0"/>
  </material>
  <material name="Black">
    <color rgba="0.1 0.1 0.1 1.0"/>
  </material>
  <material name="LightGrey">
    <color rgba="0.6 0.6 0.6 1.0"/>
  </material>
  <material name="DarkGrey">
    <color rgba="0.25 0.25 0.25 1.0"/>
  </material>
  <material name="Orange">
    <color rgba="1.0 0.33 0.0 1.0"/>
  </material>
  <material name="sergio_description/white">
    <texture filename="package://sergio_description/media/materials/textures/white/white.jpg"/>
  </material>
  <material name="sergio_description/logo">
    <texture filename="package://sergio_description/media/materials/textures/logo/tue.jpg"/>
  </material>
  <material name="sergio_description/aluminium">
    <texture filename="package://sergio_description/media/materials/textures/aluminium/aluminium_0001_c.jpg"/>
  </material>
  <material name="sergio_description/orange">
    <texture filename="package://sergio_description/media/materials/textures/orange/orange.jpg"/>
  </material>
  <author>Janno Lunenburg</author>
  <license>BSD</license>
  <review notes="" status="unreviewed"/>
  <link name="base_link">
    <inertial>
      <origin rpy="0 0 0" xyz="0.0 0.0 0.0"/>
      <mass value="0"/>
      <inertia ixx="0" ixy="0" ixz="0" iyy="0" iyz="0" izz="0"/>
    </inertial>
    <visual>
      <origin rpy="0 0 0" xyz="0.0 0.0 0.0"/>
      <geometry>
        <cylinder length="0.00" radius="0.0"/>
      </geometry>
      <material name="White">
         </material>
    </visual>
    <collision>
      <origin rpy="0 0 0" xyz="0.0 0.0 0.0"/>
      <geometry>
        <cylinder length="0.00" radius="0.0"/>
      </geometry>
    </collision>
  </link>
  <link name="base">
    <inertial>
      <origin rpy="0 0 1.57" xyz="-0.295 0.10 -0.14"/>
      <mass value="0.1"/>
      <inertia ixx="0.001" ixy="0" ixz="0" iyy="0.001" iyz="0" izz="0.001"/>
    </inertial>
    <visual>
      <origin rpy="0 0 1.57" xyz="-0.295 0.10 -0.14"/>
      <geometry>
        <mesh filename="package://sergio_description/media/meshes/Base2.dae" scale="0.01 0.01 0.01"/>
      </geometry>
      <material name="sergio_description/white"/>
    </visual>
    <collision>
      <origin rpy="0 0 1.57" xyz="-0.295 0.10 -0.14"/>
      <geometry>
        <mesh filename="package://sergio_description/media/meshes/Base2.dae" scale="0.01 0.01 0.01"/>
      </geometry>
    </collision>
  </link>
  <link name="base_block">
    <inertial>
      <origin rpy="0 0 0" xyz="-0.02 0.0 0.0"/>
      <mass value="0.1"/>
      <inertia ixx="0.001" ixy="0" ixz="0" iyy="0.001" iyz="0" izz="0.001"/>
    </inertial>
    <visual>
      <origin rpy="0 0 0" xyz="-0.02 0.0 0.0"/>
      <geometry>
        <box size="0.68 0.45 0.11"/>
      </geometry>
      <material name="White">
         </material>
    </visual>
    <collision>
      <origin rpy="0 0 0" xyz="-0.02 0.0 0.0"/>
      <geometry>
        <box size="0.68 0.45 0.11"/>
      </geometry>
    </collision>
  </link>
  <link name="sidepot_left">
    <inertial>
      <origin rpy="0 0 0" xyz="0.0 0.0 0.0"/>
      <mass value="0.1"/>
      <inertia ixx="0.001" ixy="0" ixz="0" iyy="0.001" iyz="0" izz="0.001"/>
    </inertial>
    <visual>
      <origin rpy="0 0 0" xyz="0.0 0.0 0.0"/>
      <geometry>
        <box size="0.360 0.0615 0.1"/>
      </geometry>
      <material name="White">
         </material>
    </visual>
    <collision>
      <origin rpy="0 0 0" xyz="0.0 0.0 0.0"/>
      <geometry>
        <box size="0.360 0.0615 0.1"/>
      </geometry>
    </collision>
  </link>
  <link name="sidepot_right">
    <inertial>
      <origin rpy="0 0 0" xyz="0.0 0.0 0.0"/>
      <mass value="0.1"/>
      <inertia ixx="0.001" ixy="0" ixz="0" iyy="0.001" iyz="0" izz="0.001"/>
    </inertial>
    <visual>
      <origin rpy="0 0 0" xyz="0.0 0.0 0.0"/>
      <geometry>
        <box size="0.360 0.0615 0.1"/>
      </geometry>
      <material name="White">
         </material>
    </visual>
    <collision>
      <origin rpy="0 0 0" xyz="0.0 0.0 0.0"/>
      <geometry>
        <box size="0.360 0.0615 0.1"/>
      </geometry>
    </collision>
  </link>
  <link name="base_torso_mount">
    <inertial>
      <origin rpy="0 0 0" xyz="0.0 0.0 0.0"/>
      <mass value="0"/>
      <inertia ixx="0" ixy="0" ixz="0" iyy="0" iyz="0" izz="0"/>
    </inertial>
    <visual>
      <origin rpy="0 0 0" xyz="0.0 0.0 0.0"/>
      <geometry>
        <cylinder length="0.00" radius="0.0"/>
      </geometry>
      <material name="White">
         </material>
    </visual>
    <collision>
      <origin rpy="0 0 0" xyz="0.0 0.0 0.0"/>
      <geometry>
        <cylinder length="0.00" radius="0.0"/>
      </geometry>
    </collision>
  </link>
  <link name="laser_mount">
    <inertial>
      <origin rpy="0 0 0" xyz="0.005 0.0 0.0175"/>
      <mass value="0.01"/>
      <inertia ixx="0.0001" ixy="0" ixz="0" iyy="0.0001" iyz="0" izz="0.0001"/>
    </inertial>
    <visual>
      <origin rpy="0 0 0" xyz="0.005 0.0 0.0175"/>
      <geometry>
        <box size="0.01 0.06 0.035"/>
      </geometry>
      <material name="White">
         </material>
    </visual>
    <collision>
      <origin rpy="0 0 0" xyz="0.005 0.0 0.0175"/>
      <geometry>
        <box size="0.01 0.06 0.035"/>
      </geometry>
    </collision>
  </link>
  <link name="back_laser_mount">
    <inertial>
      <origin rpy="0 0 0" xyz="0.0 0.0 -0.005"/>
      <mass value="0.01"/>
      <inertia ixx="0.0001" ixy="0" ixz="0" iyy="0.0001" iyz="0" izz="0.0001"/>
    </inertial>
    <visual>
      <origin rpy="0 0 0" xyz="0.0 0.0 -0.005"/>
      <geometry>
        <box size="0.06 0.28 0.01"/>
      </geometry>
      <material name="White">
         </material>
    </visual>
    <collision>
      <origin rpy="0 0 0" xyz="0.0 0.0 -0.005"/>
      <geometry>
        <box size="0.06 0.28 0.01"/>
      </geometry>
    </collision>
  </link>
  <link name="wheel_right_front">
    <inertial>
      <origin rpy="0.0 0 0" xyz="0.0 0.0 0.0"/>
      <mass value="0"/>
      <inertia ixx="0" ixy="0" ixz="0" iyy="0" iyz="0" izz="0"/>
    </inertial>
    <visual>
      <origin rpy="0.0 0 0" xyz="0.0 0.0 0.0"/>
      <geometry>
        <cylinder length="0.055" radius="0.075"/>
      </geometry>
      <material name="DarkGrey">
         </material>
    </visual>
    <collision>
      <origin rpy="0.0 0 0" xyz="0.0 0.0 0.0"/>
      <geometry>
        <cylinder length="0.055" radius="0.075"/>
      </geometry>
    </collision>
  </link>
  <link name="wheel_left_front">
    <inertial>
      <origin rpy="0.0 0 0" xyz="0.0 0.0 0.0"/>
      <mass value="0"/>
      <inertia ixx="0" ixy="0" ixz="0" iyy="0" iyz="0" izz="0"/>
    </inertial>
    <visual>
      <origin rpy="0.0 0 0" xyz="0.0 0.0 0.0"/>
      <geometry>
        <cylinder length="0.055" radius="0.075"/>
      </geometry>
      <material name="DarkGrey">
         </material>
    </visual>
    <collision>
      <origin rpy="0.0 0 0" xyz="0.0 0.0 0.0"/>
      <geometry>
        <cylinder length="0.055" radius="0.075"/>
      </geometry>
    </collision>
  </link>
  <link name="wheel_right_rear">
    <inertial>
      <origin rpy="0.0 0 0" xyz="0.0 0.0 0.0"/>
      <mass value="0"/>
      <inertia ixx="0" ixy="0" ixz="0" iyy="0" iyz="0" izz="0"/>
    </inertial>
    <visual>
      <origin rpy="0.0 0 0" xyz="0.0 0.0 0.0"/>
      <geometry>
        <cylinder length="0.055" radius="0.075"/>
      </geometry>
      <material name="DarkGrey">
         </material>
    </visual>
    <collision>
      <origin rpy="0.0 0 0" xyz="0.0 0.0 0.0"/>
      <geometry>
        <cylinder length="0.055" radius="0.075"/>
      </geometry>
    </collision>
  </link>
  <link name="wheel_left_rear">
    <inertial>
      <origin rpy="0.0 0 0" xyz="0.0 0.0 0.0"/>
      <mass value="0"/>
      <inertia ixx="0" ixy="0" ixz="0" iyy="0" iyz="0" izz="0"/>
    </inertial>
    <visual>
      <origin rpy="0.0 0 0" xyz="0.0 0.0 0.0"/>
      <geometry>
        <cylinder length="0.055" radius="0.075"/>
      </geometry>
      <material name="DarkGrey">
         </material>
    </visual>
    <collision>
      <origin rpy="0.0 0 0" xyz="0.0 0.0 0.0"/>
      <geometry>
        <cylinder length="0.055" radius="0.075"/>
      </geometry>
    </collision>
  </link>
  <link name="batteries">
    <inertial>
      <origin rpy="0 0 0" xyz="0.0 0.0 0.0"/>
      <mass value="0.1"/>
      <inertia ixx="0.001" ixy="0" ixz="0" iyy="0.001" iyz="0" izz="0.001"/>
    </inertial>
    <visual>
      <origin rpy="0 0 0" xyz="0.0 0.0 0.0"/>
      <geometry>
        <box size="0.332 0.117 0.08"/>
      </geometry>
      <material name="Black">
         </material>
    </visual>
    <collision>
      <origin rpy="0 0 0" xyz="0.0 0.0 0.0"/>
      <geometry>
        <box size="0.332 0.117 0.08"/>
      </geometry>
    </collision>
  </link>
  <!-- joints -->
  <joint name="base_link_joint" type="fixed">
    <parent link="base_link"/>
    <child link="base"/>
    <axis xyz="1 0 0"/>
    <origin rpy="0 0 0" xyz="0.0 0.0 0.085"/>
    <!--ToDO: adjust height-->
  </joint>
  <joint name="base_block_joint" type="fixed">
    <parent link="base"/>
    <child link="base_block"/>
    <axis xyz="1 0 0"/>
    <origin rpy="0 0 0" xyz="0.0 0.0 0.0"/>
    <!--ToDO: adjust height-->
  </joint>
  <joint name="sidepot_left_joint" type="fixed">
    <parent link="base"/>
    <child link="sidepot_left"/>
    <axis xyz="1 0 0"/>
    <origin rpy="0 0 0" xyz="0.0 0.2425 0.045"/>
    <!--ToDO: adjust distance-->
  </joint>
  <joint name="sidepot_right_joint" type="fixed">
    <parent link="base"/>
    <child link="sidepot_right"/>
    <axis xyz="1 0 0"/>
    <origin rpy="0 0 0" xyz="0.0 -0.2425 0.045"/>
    <!--ToDO: adjust distance-->
  </joint>
  <joint name="base_mount_joint" type="fixed">
    <parent link="base"/>
    <child link="base_torso_mount"/>
    <origin rpy="0 0 0.0" xyz="0.0 0.0 0.01"/>
    <!--ToDo: adjust height 12-11-16 Matthijs: -4.5cm -->
  </joint>
  <joint name="laser_mount_joint" type="fixed">
    <parent link="base"/>
    <child link="laser_mount"/>
    <origin rpy="3.141592653589793 0.0 0.0" xyz="0.2995 0.0 0.039"/>
  </joint>
  <joint name="back_laser_mount_joint" type="fixed">
    <parent link="base"/>
    <child link="back_laser_mount"/>
    <origin rpy="0.0 0.0 0.0" xyz="-0.293 0.0 0.157"/>
  </joint>
  <joint name="wheel_right_front_joint" type="fixed">
    <parent link="base_link"/>
    <child link="wheel_right_front"/>
    <origin rpy="1.57 0.0 0.0" xyz="0.265 -0.275 0.075"/>
  </joint>
  <joint name="wheel_left_front_joint" type="fixed">
    <parent link="base_link"/>
    <child link="wheel_left_front"/>
    <origin rpy="1.57 0.0 0.0" xyz="0.265 0.275 0.075"/>
  </joint>
  <joint name="wheel_right_rear_joint" type="fixed">
    <parent link="base_link"/>
    <child link="wheel_right_rear"/>
    <origin rpy="1.57 0.0 0.0" xyz="-0.265 -0.275 0.075"/>
  </joint>
  <joint name="wheel_left_rear_joint" type="fixed">
    <parent link="base_link"/>
    <child link="wheel_left_rear"/>
    <origin rpy="1.57 0.0 0.0" xyz="-0.265 0.275 0.075"/>
  </joint>
  <joint name="battery_joint" type="fixed">
    <parent link="base_link"/>
    <child link="batteries"/>
    <origin rpy="0.0 0.0 0.0" xyz="0.0 0.2335 0.194"/>
  </joint>
  <author>Rob Janssen, Kris van Tienhoven</author>
  <license>BSD</license>
  <review notes="" status="unreviewed"/>
  <link name="torso_mounting_frame">
    <inertial>
      <origin rpy="0 0 0" xyz="0.0 0.0 0.025"/>
      <mass value="0.1"/>
      <inertia ixx="0.001" ixy="0" ixz="0" iyy="0.001" iyz="0" izz="0.001"/>
    </inertial>
    <visual>
      <origin rpy="0 0 0" xyz="0.0 0.0 0.025"/>
      <geometry>
        <box size="0.500 0.400 0.05"/>
      </geometry>
      <material name="Grey">
         </material>
    </visual>
    <collision>
      <origin rpy="0 0 0" xyz="0.0 0.0 0.025"/>
      <geometry>
        <box size="0.500 0.400 0.05"/>
      </geometry>
    </collision>
  </link>
  <link name="lower_rear_leg">
    <inertial>
      <origin rpy="0 0 0" xyz="0.195 0.0 0.0"/>
      <mass value="5"/>
      <inertia ixx="0.001" ixy="0" ixz="0" iyy="0.001" iyz="0" izz="0.001"/>
    </inertial>
    <visual>
      <origin rpy="0 0 0" xyz="0.195 0.0 0.0"/>
      <geometry>
        <box size="0.390 0.200 0.05"/>
      </geometry>
      <material name="Grey">
         </material>
    </visual>
    <collision>
      <origin rpy="0 0 0" xyz="0.195 0.0 0.0"/>
      <geometry>
        <box size="0.390 0.200 0.05"/>
      </geometry>
    </collision>
  </link>
  <link name="upper_leg">
    <inertial>
      <origin rpy="0 0 1.57" xyz="0.41575 -0.10 -0.02"/>
      <mass value="5"/>
      <inertia ixx="0.001" ixy="0" ixz="0" iyy="0.001" iyz="0" izz="0.001"/>
    </inertial>
    <visual>
      <origin rpy="0 0 1.57" xyz="0.41575 -0.10 -0.02"/>
      <geometry>
        <mesh filename="package://sergio_description/media/meshes/upper_leg_reduced10000.dae" scale="0.01 0.01 0.01"/>
      </geometry>
      <material name="sergio_description/white"/>
    </visual>
    <collision>
      <origin rpy="0 0 1.57" xyz="0.41575 -0.10 -0.02"/>
      <geometry>
        <mesh filename="package://sergio_description/media/meshes/upper_leg_reduced10000.dae" scale="0.01 0.01 0.01"/>
      </geometry>
    </collision>
  </link>
  <link name="upper_leg_inside">
    <inertial>
      <origin rpy="0 0 0" xyz="0.20 0.0 0.0"/>
      <mass value="0.001"/>
      <inertia ixx="0.001" ixy="0" ixz="0" iyy="0.001" iyz="0" izz="0.001"/>
    </inertial>
    <visual>
      <origin rpy="0 0 0" xyz="0.20 0.0 0.0"/>
      <geometry>
        <box size="0.5115 0.200 0.06"/>
      </geometry>
      <material name="Black">
         </material>
    </visual>
    <collision>
      <origin rpy="0 0 0" xyz="0.20 0.0 0.0"/>
      <geometry>
        <box size="0.5115 0.200 0.06"/>
      </geometry>
    </collision>
  </link>
  <link name="trunk">
    <inertial>
      <origin rpy="3.1415 1.73 0" xyz="0.16 -0.11 0.0"/>
      <mass value="10"/>
      <inertia ixx="0.001" ixy="0" ixz="0" iyy="0.001" iyz="0" izz="0.001"/>
    </inertial>
    <visual>
      <origin rpy="3.1415 1.73 0" xyz="0.16 -0.11 0.0"/>
      <geometry>
        <mesh filename="package://sergio_description/media/meshes/torso.dae" scale="0.01 0.01 0.01"/>
      </geometry>
      <material name="sergio_description/white"/>
    </visual>
    <collision>
      <origin rpy="3.1415 1.73 0" xyz="0.16 -0.11 0.0"/>
      <geometry>
        <mesh filename="package://sergio_description/media/meshes/torso.dae" scale="0.01 0.01 0.01"/>
      </geometry>
    </collision>
  </link>
  <link name="trunk_inside">
    <inertial>
      <origin rpy="0 0 0" xyz="0.235 0.0 0.0"/>
      <mass value="0.001"/>
      <inertia ixx="0.001" ixy="0" ixz="0" iyy="0.001" iyz="0" izz="0.001"/>
    </inertial>
    <visual>
      <origin rpy="0 0 0" xyz="0.235 0.0 0.0"/>
      <geometry>
        <box size="0.470 0.200 0.075"/>
      </geometry>
      <material name="Black">
         </material>
    </visual>
    <collision>
      <origin rpy="0 0 0" xyz="0.235 0.0 0.0"/>
      <geometry>
        <box size="0.470 0.200 0.075"/>
      </geometry>
    </collision>
  </link>
  --&gt;
    
    
    
  <link name="torso_laser_mount">
    <inertial>
      <origin rpy="0 0 0" xyz="0.0 0.0 0.0"/>
      <mass value="0.01"/>
      <inertia ixx="0.0001" ixy="0" ixz="0" iyy="0.0001" iyz="0" izz="0.0001"/>
    </inertial>
    <visual>
      <origin rpy="0 0 0" xyz="0.0 0.0 0.0"/>
      <geometry>
        <box size="0.0 0.0 0.0"/>
      </geometry>
      <material name="Black">
         </material>
    </visual>
    <collision>
      <origin rpy="0 0 0" xyz="0.0 0.0 0.0"/>
      <geometry>
        <box size="0.0 0.0 0.0"/>
      </geometry>
    </collision>
  </link>
  <!-- joints -->
  <joint name="torso_mount_joint" type="fixed">
    <parent link="base_torso_mount"/>
    <child link="torso_mounting_frame"/>
    <origin rpy="0 0 0.0" xyz="0.0 0.0 0.05"/>
    <!--ToDo: adjust height-->
  </joint>
  <joint name="ankle_joint" type="revolute">
    <parent link="torso_mounting_frame"/>
    <child link="lower_rear_leg"/>
    <origin rpy="0 0 0" xyz="-0.185 0.0 0.0565"/>
    <axis xyz="0 -1 0"/>
    <dynamics damping="6.0" friction="4.87"/>
    <limit effort="0.3" lower="0.152" upper="1.00" velocity="0.265"/>
  </joint>
  <joint name="knee_joint" type="revolute">
    <parent link="lower_rear_leg"/>
    <child link="upper_leg"/>
    <origin rpy="3.14 3.14 0.0" xyz="0.390 0.0 0.0"/>
    <axis xyz="0 -1 0"/>
    <dynamics damping="6.0" friction="4.87"/>
    <limit effort="0.3" lower="0.419" upper="2.059" velocity="0.539"/>
  </joint>
  <joint name="upper_leg_inside_joint" type="fixed">
    <parent link="upper_leg"/>
    <child link="upper_leg_inside"/>
    <origin rpy="0 0 0.0" xyz="0.0 0.0 0.0"/>
  </joint>
  <joint name="hip_joint" type="revolute">
    <parent link="upper_leg"/>
    <child link="trunk"/>
    <origin rpy="3.14 3.14 0.0" xyz="0.4115 0.0 0.0"/>
    <axis xyz="0 -1 0"/>
    <dynamics damping="6.0" friction="4.87"/>
    <limit effort="0.3" lower="1.007" upper="2.31" velocity="0.375"/>
  </joint>
  <joint name="trunk_inside_joint" type="fixed">
    <parent link="trunk"/>
    <child link="trunk_inside"/>
    <origin rpy="0 0 0.0" xyz="0.0 0.0 0.0"/>
  </joint>
  <joint name="laser_tilt_joint" type="revolute">
    <parent link="trunk"/>
    <child link="torso_laser_mount"/>
    <origin rpy="3.14 1.406 0.0 " xyz="0.3073 0.0 -0.0871"/>
    <dynamics damping="0.1" friction="0"/>
    <!--ToDo: update-->
    <axis xyz="0 1 0"/>
    <limit effort="13.4" lower="0.0" upper="0.324" velocity="1.0"/>
    <!--ToDo: update-->
  </joint>
  <author>Rob Janssen, Kris van Tienhoven, Janno Lunenburg</author>
  <license>BSD</license>
  <review notes="" status="unreviewed"/>
  <link name="shoulder_mount_right">
    <inertial>
      <origin rpy="1.57 0 0" xyz="0.0 -0.155 0.0"/>
      <mass value="0.15"/>
      <inertia ixx="0.01" ixy="0" ixz="0" iyy="0.01" iyz="0" izz="0.01"/>
    </inertial>
    <visual>
      <origin rpy="1.57 0 0 " xyz="0.0 -0.155 0.0"/>
      <geometry>
        <cylinder length="0.140" radius="0.075"/>
      </geometry>
      <material name="White">
         </material>
    </visual>
    <collision>
      <origin rpy="1.57 0 0 " xyz="0.0 -0.155 0.0"/>
      <geometry>
        <cylinder length="0.140" radius="0.075"/>
      </geometry>
    </collision>
  </link>
  <!-- ${sidesign*-0.155} -->
  <link name="shoulder_link1_right">
    <inertial>
      <origin rpy="0 0 0" xyz="0.0 0.0 0.0"/>
      <mass value="0.25"/>
      <inertia ixx="6.0" ixy="0" ixz="0" iyy="0.01" iyz="0" izz="0.01"/>
    </inertial>
    <visual>
      <origin rpy="0 0 0 " xyz="0.0 0.0 0.0525"/>
      <geometry>
        <cylinder length="0.015" radius="0.045"/>
      </geometry>
      <material name="Black">
         </material>
    </visual>
    <collision>
      <origin rpy="0 0 0 " xyz="0.0 0.0 0.0525"/>
      <geometry>
        <cylinder length="0.015" radius="0.045"/>
      </geometry>
    </collision>
  </link>
  <link name="shoulder_link2_right">
    <inertial>
      <origin rpy="0 0 0" xyz="0.0 0.0 0.0"/>
      <mass value="0.15"/>
      <inertia ixx="0.01" ixy="0" ixz="0" iyy="4.04" iyz="0" izz="0.001"/>
    </inertial>
    <visual>
      <origin rpy="0 0 0" xyz="0.0 -0.06 -0.05"/>
      <geometry>
        <box size="0.035 0.01 0.1"/>
      </geometry>
      <material name="Black">
         </material>
    </visual>
    <collision>
      <origin rpy="0 0 0" xyz="0.0 -0.06 -0.05"/>
      <geometry>
        <box size="0.035 0.01 0.1"/>
      </geometry>
    </collision>
  </link>
  <link name="upper_arm_right">
    <inertial>
      <origin rpy="0 0 0" xyz="0.0 -0.2 0.0"/>
      <mass value="2.95"/>
      <inertia ixx="0.027" ixy="0" ixz="0" iyy="0.45993" iyz="0" izz="0.004"/>
    </inertial>
    <visual>
      <origin rpy="0 0 3.1415" xyz="-0.00959 -0.19131 -0.00001"/>
      <geometry>
        <mesh filename="package://sergio_description/media/meshes/upperarmtextured.dae" scale="0.0004 0.0004 0.0004"/>
      </geometry>
      <material name="sergio_description/white"/>
    </visual>
    <collision>
      <origin rpy="0 0 3.1415" xyz="-0.00959 -0.19131 -0.00001"/>
      <geometry>
        <mesh filename="package://sergio_description/media/meshes/upperarmtextured.dae" scale="0.0004 0.0004 0.0004"/>
      </geometry>
    </collision>
  </link>
  <link name="elbow_link4_right">
    <inertial>
      <origin rpy="0 0 0" xyz="0.0 0.0 0.0"/>
      <mass value="0.1"/>
      <inertia ixx="0.001" ixy="0" ixz="0" iyy="0.6" iyz="0" izz="0.001"/>
    </inertial>
    <visual>
      <origin rpy="0 0 0" xyz="0.0 0.0 0.0"/>
      <geometry>
        <cylinder length="0.0" radius="0.0"/>
      </geometry>
      <material name="Grey">
         </material>
    </visual>
    <collision>
      <origin rpy="0 0 0" xyz="0.0 0.0 0.0"/>
      <geometry>
        <cylinder length="0.0" radius="0.0"/>
      </geometry>
    </collision>
  </link>
  <link name="fore_arm_right">
    <inertial>
      <origin rpy="0.0 0 0" xyz="0.0 -0.14 0.0"/>
      <mass value="0.85"/>
      <inertia ixx="0.001" ixy="0" ixz="0" iyy="0.5" iyz="0" izz="0.001"/>
    </inertial>
    <visual>
      <origin rpy="0 -1.5708 0" xyz="0.00425 -0.14868 0.00547"/>
      <geometry>
        <mesh filename="package://sergio_description/media/meshes/forearmtextured.dae" scale="0.0004 0.0004 0.0004"/>
      </geometry>
      <material name="sergio_description/white"/>
    </visual>
    <collision>
      <origin rpy="0 -1.5708 0" xyz="0.00425 -0.14868 0.00547"/>
      <geometry>
        <mesh filename="package://sergio_description/media/meshes/forearmtextured.dae" scale="0.0004 0.0004 0.0004"/>
      </geometry>
    </collision>
  </link>
  <link name="wrist_link6_right">
    <inertial>
      <origin rpy="0 0 0" xyz="0.0 0.0 0.0"/>
      <mass value="0.01"/>
      <inertia ixx="0.001" ixy="0" ixz="0" iyy="0.03322" iyz="0" izz="0.001"/>
    </inertial>
    <visual>
      <origin rpy="1.5708 0 0" xyz="0.0 0.0 0.0"/>
      <geometry>
        <cylinder length="0.0" radius="0.0"/>
      </geometry>
      <material name="Black">
         </material>
    </visual>
    <collision>
      <origin rpy="1.5708 0 0" xyz="0.0 0.0 0.0"/>
      <geometry>
        <cylinder length="0.0" radius="0.0"/>
      </geometry>
    </collision>
  </link>
  <link name="hand_right">
    <inertial>
      <origin rpy="0 0 0" xyz="0.048 0.0 0.0"/>
      <mass value="0.2"/>
      <inertia ixx="0.01" ixy="0" ixz="0" iyy="0.01" iyz="0" izz="0.0622"/>
    </inertial>
    <visual>
      <origin rpy="0 0 0" xyz="0.048 0.0 0.0"/>
      <geometry>
        <box size="0.080 0.085 0.038"/>
      </geometry>
      <material name="Grey">
         </material>
    </visual>
    <collision>
      <origin rpy="0 0 0" xyz="0.048 0.0 0.0"/>
      <geometry>
        <box size="0.080 0.085 0.038"/>
      </geometry>
    </collision>
  </link>
  <link name="finger1_right">
    <inertial>
      <origin rpy="0 0 0" xyz="0.0 0.0 -0.03"/>
      <mass value="0.01"/>
      <inertia ixx="0.01" ixy="0" ixz="0" iyy="0.01" iyz="0" izz="0.01"/>
    </inertial>
    <visual>
      <origin rpy="0 0 0" xyz="0.0 0.0 -0.03"/>
      <geometry>
        <box size="0.018 0.018 0.06"/>
      </geometry>
      <material name="Black">
         </material>
    </visual>
    <collision>
      <origin rpy="0 0 0" xyz="0.0 0.0 -0.03"/>
      <geometry>
        <box size="0.018 0.018 0.06"/>
      </geometry>
    </collision>
  </link>
  <link name="finger1_phalanx_right">
    <inertial>
      <origin rpy="0 0 0" xyz="0.0 0.0 0"/>
      <mass value="0.01"/>
      <inertia ixx="0.001" ixy="0" ixz="0" iyy="0.001" iyz="0" izz="0.001"/>
    </inertial>
    <visual>
      <origin rpy="0 0 0" xyz="0.0 0.0 0"/>
      <geometry>
        <cylinder length="0.019" radius="0.009"/>
      </geometry>
      <material name="White">
         </material>
    </visual>
    <collision>
      <origin rpy="0 0 0" xyz="0.0 0.0 0"/>
      <geometry>
        <cylinder length="0.019" radius="0.009"/>
      </geometry>
    </collision>
  </link>
  <link name="finger1_tip_right">
    <inertial>
      <origin rpy="0 0 0" xyz="0.0 0.0 -0.03"/>
      <mass value="0.01"/>
      <inertia ixx="0.00037" ixy="0" ixz="0" iyy="0.00052" iyz="0" izz="0.00052"/>
    </inertial>
    <visual>
      <origin rpy="0 0 0" xyz="0.0 0.0 -0.03"/>
      <geometry>
        <box size="0.018 0.018 0.06"/>
      </geometry>
      <material name="Black">
         </material>
    </visual>
    <collision>
      <origin rpy="0 0 0" xyz="0.0 0.0 -0.03"/>
      <geometry>
        <box size="0.018 0.018 0.06"/>
      </geometry>
    </collision>
  </link>
  <link name="finger1_tip_phalanx_right">
    <inertial>
      <origin rpy="0 0 0" xyz="0.0 0.0 0"/>
      <mass value="0.01"/>
      <inertia ixx="0.001" ixy="0" ixz="0" iyy="0.001" iyz="0" izz="0.001"/>
    </inertial>
    <visual>
      <origin rpy="0 0 0" xyz="0.0 0.0 0"/>
      <geometry>
        <cylinder length="0.017" radius="0.009"/>
      </geometry>
      <material name="White">
         </material>
    </visual>
    <collision>
      <origin rpy="0 0 0" xyz="0.0 0.0 0"/>
      <geometry>
        <cylinder length="0.017" radius="0.009"/>
      </geometry>
    </collision>
  </link>
  <link name="finger2_right">
    <inertial>
      <origin rpy="0 0 0" xyz="0.0 0.0 -0.03"/>
      <mass value="0.01"/>
      <inertia ixx="0.01" ixy="0" ixz="0" iyy="0.01" iyz="0" izz="0.01"/>
    </inertial>
    <visual>
      <origin rpy="0 0 0" xyz="0.0 0.0 -0.03"/>
      <geometry>
        <box size="0.018 0.018 0.06"/>
      </geometry>
      <material name="Black">
         </material>
    </visual>
    <collision>
      <origin rpy="0 0 0" xyz="0.0 0.0 -0.03"/>
      <geometry>
        <box size="0.018 0.018 0.06"/>
      </geometry>
    </collision>
  </link>
  <link name="finger2_phalanx_right">
    <inertial>
      <origin rpy="0 0 0" xyz="0.0 0.0 0"/>
      <mass value="0.01"/>
      <inertia ixx="0.001" ixy="0" ixz="0" iyy="0.001" iyz="0" izz="0.001"/>
    </inertial>
    <visual>
      <origin rpy="0 0 0" xyz="0.0 0.0 0"/>
      <geometry>
        <cylinder length="0.019" radius="0.009"/>
      </geometry>
      <material name="White">
         </material>
    </visual>
    <collision>
      <origin rpy="0 0 0" xyz="0.0 0.0 0"/>
      <geometry>
        <cylinder length="0.019" radius="0.009"/>
      </geometry>
    </collision>
  </link>
  <link name="finger2_tip_right">
    <inertial>
      <origin rpy="0 0 0" xyz="0.0 0.0 -0.03"/>
      <mass value="0.01"/>
      <inertia ixx="0.00037" ixy="0" ixz="0" iyy="0.00052" iyz="0" izz="0.00052"/>
    </inertial>
    <visual>
      <origin rpy="0 0 0" xyz="0.0 0.0 -0.03"/>
      <geometry>
        <box size="0.018 0.018 0.06"/>
      </geometry>
      <material name="Black">
         </material>
    </visual>
    <collision>
      <origin rpy="0 0 0" xyz="0.0 0.0 -0.03"/>
      <geometry>
        <box size="0.018 0.018 0.06"/>
      </geometry>
    </collision>
  </link>
  <link name="finger2_tip_phalanx_right">
    <inertial>
      <origin rpy="0 0 0" xyz="0.0 0.0 0"/>
      <mass value="0.01"/>
      <inertia ixx="0.001" ixy="0" ixz="0" iyy="0.001" iyz="0" izz="0.001"/>
    </inertial>
    <visual>
      <origin rpy="0 0 0" xyz="0.0 0.0 0"/>
      <geometry>
        <cylinder length="0.017" radius="0.009"/>
      </geometry>
      <material name="White">
         </material>
    </visual>
    <collision>
      <origin rpy="0 0 0" xyz="0.0 0.0 0"/>
      <geometry>
        <cylinder length="0.017" radius="0.009"/>
      </geometry>
    </collision>
  </link>
  <link name="grippoint_right">
    <inertial>
      <origin rpy="0 0 0" xyz="-0.1 0.0 0.0"/>
      <mass value="0.01"/>
      <inertia ixx="0.0001" ixy="0" ixz="0" iyy="0.0001" iyz="0" izz="0.0001"/>
    </inertial>
    <visual>
      <origin rpy="0 0 0 " xyz="-0.1 0.0 0.0"/>
      <geometry>
        <box size="0.0 0.0 0.0"/>
      </geometry>
      <material name="Blue">
         </material>
    </visual>
    <collision>
      <origin rpy="0 0 0 " xyz="-0.1 0.0 0.0"/>
      <geometry>
        <box size="0.0 0.0 0.0"/>
      </geometry>
    </collision>
  </link>
  <!--the joints start here-->
  <joint name="shoulder_mount_joint_right" type="fixed">
    <parent link="trunk"/>
    <child link="shoulder_mount_right"/>
    <origin rpy="3.14 0 0.0" xyz="0.470 -0.22 0.0"/>
    <!-- Check length -->
  </joint>
  <joint name="shoulder_yaw_joint_right" type="revolute">
    <parent link="shoulder_mount_right"/>
    <child link="shoulder_link1_right"/>
    <origin rpy="-1.5708 -1.5708 0" xyz="0 0 0"/>
    <axis xyz="+1 0 0"/>
    <dynamics damping="4.0" friction="4.87"/>
    <limit effort="13.4" lower="-1.57" upper="0.0" velocity="1.0"/>
  </joint>
  <joint name="shoulder_pitch_joint_right" type="revolute">
    <parent link="shoulder_link1_right"/>
    <child link="shoulder_link2_right"/>
    <origin rpy="-1.5708  0 0" xyz="0.0 0.0 0.0"/>
    <axis xyz="0 -1 0"/>
    <dynamics damping="4.0" friction="6.06"/>
    <limit effort="13.4" lower="-1.57" upper="1.57" velocity="1.0"/>
  </joint>
  <joint name="shoulder_roll_joint_right" type="revolute">
    <parent link="shoulder_link2_right"/>
    <child link="upper_arm_right"/>
    <origin rpy="1.5708 0 0.0" xyz="0.0 0.0 0.0"/>
    <axis xyz="0 1 0"/>
    <dynamics damping="3.8" friction="2.216"/>
    <limit effort="9.8" lower="-1.57" upper="1.57" velocity="1.0"/>
  </joint>
  <joint name="elbow_pitch_joint_right" type="revolute">
    <parent link="upper_arm_right"/>
    <child link="elbow_link4_right"/>
    <origin rpy="-1.5708 0 0" xyz="0.01 -0.32 0.0"/>
    <axis xyz="0 -1 0"/>
    <dynamics damping="3" friction="1.18"/>
    <limit effort="4.5" lower="0.0" upper="2.23" velocity="1.0"/>
  </joint>
  <joint name="elbow_roll_joint_right" type="revolute">
    <parent link="elbow_link4_right"/>
    <child link="fore_arm_right"/>
    <origin rpy="1.5708 0 0" xyz="0.0 0.0 0.0"/>
    <axis xyz="0 1 0"/>
    <dynamics damping="3.5" friction="1.35"/>
    <limit effort="4.5" lower="-1.83" upper="1.83" velocity="1.0"/>
  </joint>
  <joint name="wrist_pitch_joint_right" type="revolute">
    <parent link="fore_arm_right"/>
    <child link="wrist_link6_right"/>
    <origin rpy="-1.5708 0 -1.5708" xyz="0.01 -0.28 0.0"/>
    <axis xyz="0 -1 0"/>
    <dynamics damping="0.35" friction="0.63"/>
    <limit effort="1" lower="-0.95" upper="0.95" velocity="1.0"/>
  </joint>
  <joint name="wrist_yaw_joint_right" type="revolute">
    <parent link="wrist_link6_right"/>
    <child link="hand_right"/>
    <origin rpy="0 0 0" xyz="0.0 0.0 0.0"/>
    <axis xyz="0 0 11"/>
    <dynamics damping="0.3" friction="0.68"/>
    <limit effort="1" lower="-0.61" upper="0.61" velocity="1.0"/>
  </joint>
  <joint name="finger1_joint_right" type="revolute">
    <parent link="hand_right"/>
    <child link="finger1_right"/>
    <origin rpy="0 -1.57 0" xyz=" 0.075 0.02 0"/>
    <axis xyz="1 0 0"/>
    <dynamics damping="0.5" friction="1.0"/>
    <limit effort="3" lower="-1.57" upper="1.57" velocity="1.0"/>
  </joint>
  <joint name="finger1_phalanx_joint_right" type="fixed">
    <parent link="finger1_right"/>
    <child link="finger1_phalanx_right"/>
    <origin rpy="0 1.57 0" xyz="0 0 -0.06"/>
  </joint>
  <joint name="finger1_tip_joint_right" type="revolute">
    <parent link="finger1_right"/>
    <child link="finger1_tip_right"/>
    <origin rpy="0 0 0" xyz=" 0 0.0 -0.06"/>
    <axis xyz="1 0 0"/>
    <dynamics damping="0.5" friction="1.0"/>
    <limit effort="3" lower="-1.57" upper="1.57" velocity="1.0"/>
  </joint>
  <joint name="finger1_tip_phalanx_joint_right" type="fixed">
    <parent link="finger1_tip_right"/>
    <child link="finger1_tip_phalanx_right"/>
    <origin rpy="0 1.57 0" xyz="0 0 -0.06"/>
  </joint>
  <joint name="finger2_joint_right" type="revolute">
    <parent link="hand_right"/>
    <child link="finger2_right"/>
    <origin rpy="0 -1.57 0" xyz="0.075 -0.02 0"/>
    <axis xyz="-1 0 0"/>
    <dynamics damping="0.5" friction="1.0"/>
    <limit effort="3" lower="-1.57" upper="1.57" velocity="1.0"/>
  </joint>
  <joint name="finger2_phalanx_joint_right" type="fixed">
    <parent link="finger2_right"/>
    <child link="finger2_phalanx_right"/>
    <origin rpy="0 1.57 0" xyz="0 0 -0.06"/>
  </joint>
  <joint name="finger2_tip_joint_right" type="revolute">
    <parent link="finger2_right"/>
    <child link="finger2_tip_right"/>
    <origin rpy="0 0 0" xyz="0 0 -0.06"/>
    <axis xyz="-1 0 0"/>
    <dynamics damping="0.5" friction="1.0"/>
    <limit effort="3" lower="-1.57" upper="1.57" velocity="1.0"/>
  </joint>
  <joint name="finger2_tip_phalanx_joint_right" type="fixed">
    <parent link="finger2_tip_right"/>
    <child link="finger2_tip_phalanx_right"/>
    <origin rpy="0 1.57 0" xyz="0 0 -0.06"/>
  </joint>
  <joint name="grippoint_joint_right" type="fixed">
    <parent link="hand_right"/>
    <child link="grippoint_right"/>
    <origin rpy="0 0 0" xyz="0.14 0.0 0.0"/>
  </joint>
  <link name="shoulder_mount_left">
    <inertial>
      <origin rpy="1.57 0 0" xyz="0.0 0.155 0.0"/>
      <mass value="0.15"/>
      <inertia ixx="0.01" ixy="0" ixz="0" iyy="0.01" iyz="0" izz="0.01"/>
    </inertial>
    <visual>
      <origin rpy="1.57 0 0 " xyz="0.0 0.155 0.0"/>
      <geometry>
        <cylinder length="0.140" radius="0.075"/>
      </geometry>
      <material name="White">
         </material>
    </visual>
    <collision>
      <origin rpy="1.57 0 0 " xyz="0.0 0.155 0.0"/>
      <geometry>
        <cylinder length="0.140" radius="0.075"/>
      </geometry>
    </collision>
  </link>
  <!-- ${sidesign*-0.155} -->
  <link name="shoulder_link1_left">
    <inertial>
      <origin rpy="0 0 0" xyz="0.0 0.0 0.0"/>
      <mass value="0.25"/>
      <inertia ixx="6.0" ixy="0" ixz="0" iyy="0.01" iyz="0" izz="0.01"/>
    </inertial>
    <visual>
      <origin rpy="0 0 0 " xyz="0.0 0.0 -0.0525"/>
      <geometry>
        <cylinder length="0.015" radius="0.045"/>
      </geometry>
      <material name="Black">
         </material>
    </visual>
    <collision>
      <origin rpy="0 0 0 " xyz="0.0 0.0 -0.0525"/>
      <geometry>
        <cylinder length="0.015" radius="0.045"/>
      </geometry>
    </collision>
  </link>
  <link name="shoulder_link2_left">
    <inertial>
      <origin rpy="0 0 0" xyz="0.0 0.0 0.0"/>
      <mass value="0.15"/>
      <inertia ixx="0.01" ixy="0" ixz="0" iyy="4.04" iyz="0" izz="0.001"/>
    </inertial>
    <visual>
      <origin rpy="0 0 0" xyz="0.0 0.06 -0.05"/>
      <geometry>
        <box size="0.035 0.01 0.1"/>
      </geometry>
      <material name="Black">
         </material>
    </visual>
    <collision>
      <origin rpy="0 0 0" xyz="0.0 0.06 -0.05"/>
      <geometry>
        <box size="0.035 0.01 0.1"/>
      </geometry>
    </collision>
  </link>
  <link name="upper_arm_left">
    <inertial>
      <origin rpy="0 0 0" xyz="0.0 -0.2 0.0"/>
      <mass value="2.95"/>
      <inertia ixx="0.027" ixy="0" ixz="0" iyy="0.45993" iyz="0" izz="0.004"/>
    </inertial>
    <visual>
      <origin rpy="0 0 3.1415" xyz="-0.00959 -0.19131 -0.00001"/>
      <geometry>
        <mesh filename="package://sergio_description/media/meshes/upperarmtextured.dae" scale="0.0004 0.0004 0.0004"/>
      </geometry>
      <material name="sergio_description/white"/>
    </visual>
    <collision>
      <origin rpy="0 0 3.1415" xyz="-0.00959 -0.19131 -0.00001"/>
      <geometry>
        <mesh filename="package://sergio_description/media/meshes/upperarmtextured.dae" scale="0.0004 0.0004 0.0004"/>
      </geometry>
    </collision>
  </link>
  <link name="elbow_link4_left">
    <inertial>
      <origin rpy="0 0 0" xyz="0.0 0.0 0.0"/>
      <mass value="0.1"/>
      <inertia ixx="0.001" ixy="0" ixz="0" iyy="0.6" iyz="0" izz="0.001"/>
    </inertial>
    <visual>
      <origin rpy="0 0 0" xyz="0.0 0.0 0.0"/>
      <geometry>
        <cylinder length="0.0" radius="0.0"/>
      </geometry>
      <material name="Grey">
         </material>
    </visual>
    <collision>
      <origin rpy="0 0 0" xyz="0.0 0.0 0.0"/>
      <geometry>
        <cylinder length="0.0" radius="0.0"/>
      </geometry>
    </collision>
  </link>
  <link name="fore_arm_left">
    <inertial>
      <origin rpy="0.0 0 0" xyz="0.0 -0.14 0.0"/>
      <mass value="0.85"/>
      <inertia ixx="0.001" ixy="0" ixz="0" iyy="0.5" iyz="0" izz="0.001"/>
    </inertial>
    <visual>
      <origin rpy="0 -1.5708 0" xyz="0.00425 -0.14868 0.00547"/>
      <geometry>
        <mesh filename="package://sergio_description/media/meshes/forearmtextured.dae" scale="0.0004 0.0004 0.0004"/>
      </geometry>
      <material name="sergio_description/white"/>
    </visual>
    <collision>
      <origin rpy="0 -1.5708 0" xyz="0.00425 -0.14868 0.00547"/>
      <geometry>
        <mesh filename="package://sergio_description/media/meshes/forearmtextured.dae" scale="0.0004 0.0004 0.0004"/>
      </geometry>
    </collision>
  </link>
  <link name="wrist_link6_left">
    <inertial>
      <origin rpy="0 0 0" xyz="0.0 0.0 0.0"/>
      <mass value="0.01"/>
      <inertia ixx="0.001" ixy="0" ixz="0" iyy="0.03322" iyz="0" izz="0.001"/>
    </inertial>
    <visual>
      <origin rpy="1.5708 0 0" xyz="0.0 0.0 0.0"/>
      <geometry>
        <cylinder length="0.0" radius="0.0"/>
      </geometry>
      <material name="Black">
         </material>
    </visual>
    <collision>
      <origin rpy="1.5708 0 0" xyz="0.0 0.0 0.0"/>
      <geometry>
        <cylinder length="0.0" radius="0.0"/>
      </geometry>
    </collision>
  </link>
  <link name="hand_left">
    <inertial>
      <origin rpy="0 0 0" xyz="0.048 0.0 0.0"/>
      <mass value="0.2"/>
      <inertia ixx="0.01" ixy="0" ixz="0" iyy="0.01" iyz="0" izz="0.0622"/>
    </inertial>
    <visual>
      <origin rpy="0 0 0" xyz="0.048 0.0 0.0"/>
      <geometry>
        <box size="0.080 0.085 0.038"/>
      </geometry>
      <material name="Grey">
         </material>
    </visual>
    <collision>
      <origin rpy="0 0 0" xyz="0.048 0.0 0.0"/>
      <geometry>
        <box size="0.080 0.085 0.038"/>
      </geometry>
    </collision>
  </link>
  <link name="finger1_left">
    <inertial>
      <origin rpy="0 0 0" xyz="0.0 0.0 -0.03"/>
      <mass value="0.01"/>
      <inertia ixx="0.01" ixy="0" ixz="0" iyy="0.01" iyz="0" izz="0.01"/>
    </inertial>
    <visual>
      <origin rpy="0 0 0" xyz="0.0 0.0 -0.03"/>
      <geometry>
        <box size="0.018 0.018 0.06"/>
      </geometry>
      <material name="Black">
         </material>
    </visual>
    <collision>
      <origin rpy="0 0 0" xyz="0.0 0.0 -0.03"/>
      <geometry>
        <box size="0.018 0.018 0.06"/>
      </geometry>
    </collision>
  </link>
  <link name="finger1_phalanx_left">
    <inertial>
      <origin rpy="0 0 0" xyz="0.0 0.0 0"/>
      <mass value="0.01"/>
      <inertia ixx="0.001" ixy="0" ixz="0" iyy="0.001" iyz="0" izz="0.001"/>
    </inertial>
    <visual>
      <origin rpy="0 0 0" xyz="0.0 0.0 0"/>
      <geometry>
        <cylinder length="0.019" radius="0.009"/>
      </geometry>
      <material name="White">
         </material>
    </visual>
    <collision>
      <origin rpy="0 0 0" xyz="0.0 0.0 0"/>
      <geometry>
        <cylinder length="0.019" radius="0.009"/>
      </geometry>
    </collision>
  </link>
  <link name="finger1_tip_left">
    <inertial>
      <origin rpy="0 0 0" xyz="0.0 0.0 -0.03"/>
      <mass value="0.01"/>
      <inertia ixx="0.00037" ixy="0" ixz="0" iyy="0.00052" iyz="0" izz="0.00052"/>
    </inertial>
    <visual>
      <origin rpy="0 0 0" xyz="0.0 0.0 -0.03"/>
      <geometry>
        <box size="0.018 0.018 0.06"/>
      </geometry>
      <material name="Black">
         </material>
    </visual>
    <collision>
      <origin rpy="0 0 0" xyz="0.0 0.0 -0.03"/>
      <geometry>
        <box size="0.018 0.018 0.06"/>
      </geometry>
    </collision>
  </link>
  <link name="finger1_tip_phalanx_left">
    <inertial>
      <origin rpy="0 0 0" xyz="0.0 0.0 0"/>
      <mass value="0.01"/>
      <inertia ixx="0.001" ixy="0" ixz="0" iyy="0.001" iyz="0" izz="0.001"/>
    </inertial>
    <visual>
      <origin rpy="0 0 0" xyz="0.0 0.0 0"/>
      <geometry>
        <cylinder length="0.017" radius="0.009"/>
      </geometry>
      <material name="White">
         </material>
    </visual>
    <collision>
      <origin rpy="0 0 0" xyz="0.0 0.0 0"/>
      <geometry>
        <cylinder length="0.017" radius="0.009"/>
      </geometry>
    </collision>
  </link>
  <link name="finger2_left">
    <inertial>
      <origin rpy="0 0 0" xyz="0.0 0.0 -0.03"/>
      <mass value="0.01"/>
      <inertia ixx="0.01" ixy="0" ixz="0" iyy="0.01" iyz="0" izz="0.01"/>
    </inertial>
    <visual>
      <origin rpy="0 0 0" xyz="0.0 0.0 -0.03"/>
      <geometry>
        <box size="0.018 0.018 0.06"/>
      </geometry>
      <material name="Black">
         </material>
    </visual>
    <collision>
      <origin rpy="0 0 0" xyz="0.0 0.0 -0.03"/>
      <geometry>
        <box size="0.018 0.018 0.06"/>
      </geometry>
    </collision>
  </link>
  <link name="finger2_phalanx_left">
    <inertial>
      <origin rpy="0 0 0" xyz="0.0 0.0 0"/>
      <mass value="0.01"/>
      <inertia ixx="0.001" ixy="0" ixz="0" iyy="0.001" iyz="0" izz="0.001"/>
    </inertial>
    <visual>
      <origin rpy="0 0 0" xyz="0.0 0.0 0"/>
      <geometry>
        <cylinder length="0.019" radius="0.009"/>
      </geometry>
      <material name="White">
         </material>
    </visual>
    <collision>
      <origin rpy="0 0 0" xyz="0.0 0.0 0"/>
      <geometry>
        <cylinder length="0.019" radius="0.009"/>
      </geometry>
    </collision>
  </link>
  <link name="finger2_tip_left">
    <inertial>
      <origin rpy="0 0 0" xyz="0.0 0.0 -0.03"/>
      <mass value="0.01"/>
      <inertia ixx="0.00037" ixy="0" ixz="0" iyy="0.00052" iyz="0" izz="0.00052"/>
    </inertial>
    <visual>
      <origin rpy="0 0 0" xyz="0.0 0.0 -0.03"/>
      <geometry>
        <box size="0.018 0.018 0.06"/>
      </geometry>
      <material name="Black">
         </material>
    </visual>
    <collision>
      <origin rpy="0 0 0" xyz="0.0 0.0 -0.03"/>
      <geometry>
        <box size="0.018 0.018 0.06"/>
      </geometry>
    </collision>
  </link>
  <link name="finger2_tip_phalanx_left">
    <inertial>
      <origin rpy="0 0 0" xyz="0.0 0.0 0"/>
      <mass value="0.01"/>
      <inertia ixx="0.001" ixy="0" ixz="0" iyy="0.001" iyz="0" izz="0.001"/>
    </inertial>
    <visual>
      <origin rpy="0 0 0" xyz="0.0 0.0 0"/>
      <geometry>
        <cylinder length="0.017" radius="0.009"/>
      </geometry>
      <material name="White">
         </material>
    </visual>
    <collision>
      <origin rpy="0 0 0" xyz="0.0 0.0 0"/>
      <geometry>
        <cylinder length="0.017" radius="0.009"/>
      </geometry>
    </collision>
  </link>
  <link name="grippoint_left">
    <inertial>
      <origin rpy="0 0 0" xyz="-0.1 0.0 0.0"/>
      <mass value="0.01"/>
      <inertia ixx="0.0001" ixy="0" ixz="0" iyy="0.0001" iyz="0" izz="0.0001"/>
    </inertial>
    <visual>
      <origin rpy="0 0 0 " xyz="-0.1 0.0 0.0"/>
      <geometry>
        <box size="0.0 0.0 0.0"/>
      </geometry>
      <material name="Blue">
         </material>
    </visual>
    <collision>
      <origin rpy="0 0 0 " xyz="-0.1 0.0 0.0"/>
      <geometry>
        <box size="0.0 0.0 0.0"/>
      </geometry>
    </collision>
  </link>
  <!--the joints start here-->
  <joint name="shoulder_mount_joint_left" type="fixed">
    <parent link="trunk"/>
    <child link="shoulder_mount_left"/>
    <origin rpy="3.14 0 0.0" xyz="0.470 0.22 0.0"/>
    <!-- Check length -->
  </joint>
  <joint name="shoulder_yaw_joint_left" type="revolute">
    <parent link="shoulder_mount_left"/>
    <child link="shoulder_link1_left"/>
    <origin rpy="-1.5708 -1.5708 0" xyz="0 0 0"/>
    <axis xyz="-1 0 0"/>
    <dynamics damping="4.0" friction="4.87"/>
    <limit effort="13.4" lower="-1.57" upper="0.0" velocity="1.0"/>
  </joint>
  <joint name="shoulder_pitch_joint_left" type="revolute">
    <parent link="shoulder_link1_left"/>
    <child link="shoulder_link2_left"/>
    <origin rpy="-1.5708  0 0" xyz="0.0 0.0 0.0"/>
    <axis xyz="0 -1 0"/>
    <dynamics damping="4.0" friction="6.06"/>
    <limit effort="13.4" lower="-1.57" upper="1.57" velocity="1.0"/>
  </joint>
  <joint name="shoulder_roll_joint_left" type="revolute">
    <parent link="shoulder_link2_left"/>
    <child link="upper_arm_left"/>
    <origin rpy="1.5708 0 0.0" xyz="0.0 0.0 0.0"/>
    <axis xyz="0 -1 0"/>
    <dynamics damping="3.8" friction="2.216"/>
    <limit effort="9.8" lower="-1.57" upper="1.57" velocity="1.0"/>
  </joint>
  <joint name="elbow_pitch_joint_left" type="revolute">
    <parent link="upper_arm_left"/>
    <child link="elbow_link4_left"/>
    <origin rpy="-1.5708 0 0" xyz="0.01 -0.32 0.0"/>
    <axis xyz="0 -1 0"/>
    <dynamics damping="3" friction="1.18"/>
    <limit effort="4.5" lower="0.0" upper="2.23" velocity="1.0"/>
  </joint>
  <joint name="elbow_roll_joint_left" type="revolute">
    <parent link="elbow_link4_left"/>
    <child link="fore_arm_left"/>
    <origin rpy="1.5708 0 0" xyz="0.0 0.0 0.0"/>
    <axis xyz="0 -1 0"/>
    <dynamics damping="3.5" friction="1.35"/>
    <limit effort="4.5" lower="-1.83" upper="1.83" velocity="1.0"/>
  </joint>
  <joint name="wrist_pitch_joint_left" type="revolute">
    <parent link="fore_arm_left"/>
    <child link="wrist_link6_left"/>
    <origin rpy="-1.5708 0 -1.5708" xyz="0.01 -0.28 0.0"/>
    <axis xyz="0 -1 0"/>
    <dynamics damping="0.35" friction="0.63"/>
    <limit effort="1" lower="-0.95" upper="0.95" velocity="1.0"/>
  </joint>
  <joint name="wrist_yaw_joint_left" type="revolute">
    <parent link="wrist_link6_left"/>
    <child link="hand_left"/>
    <origin rpy="0 0 0" xyz="0.0 0.0 0.0"/>
    <axis xyz="0 0 -11"/>
    <dynamics damping="0.3" friction="0.68"/>
    <limit effort="1" lower="-0.61" upper="0.61" velocity="1.0"/>
  </joint>
  <joint name="finger1_joint_left" type="revolute">
    <parent link="hand_left"/>
    <child link="finger1_left"/>
    <origin rpy="0 -1.57 0" xyz=" 0.075 0.02 0"/>
    <axis xyz="1 0 0"/>
    <dynamics damping="0.5" friction="1.0"/>
    <limit effort="3" lower="-1.57" upper="1.57" velocity="1.0"/>
  </joint>
  <joint name="finger1_phalanx_joint_left" type="fixed">
    <parent link="finger1_left"/>
    <child link="finger1_phalanx_left"/>
    <origin rpy="0 1.57 0" xyz="0 0 -0.06"/>
  </joint>
  <joint name="finger1_tip_joint_left" type="revolute">
    <parent link="finger1_left"/>
    <child link="finger1_tip_left"/>
    <origin rpy="0 0 0" xyz=" 0 0.0 -0.06"/>
    <axis xyz="1 0 0"/>
    <dynamics damping="0.5" friction="1.0"/>
    <limit effort="3" lower="-1.57" upper="1.57" velocity="1.0"/>
  </joint>
  <joint name="finger1_tip_phalanx_joint_left" type="fixed">
    <parent link="finger1_tip_left"/>
    <child link="finger1_tip_phalanx_left"/>
    <origin rpy="0 1.57 0" xyz="0 0 -0.06"/>
  </joint>
  <joint name="finger2_joint_left" type="revolute">
    <parent link="hand_left"/>
    <child link="finger2_left"/>
    <origin rpy="0 -1.57 0" xyz="0.075 -0.02 0"/>
    <axis xyz="-1 0 0"/>
    <dynamics damping="0.5" friction="1.0"/>
    <limit effort="3" lower="-1.57" upper="1.57" velocity="1.0"/>
  </joint>
  <joint name="finger2_phalanx_joint_left" type="fixed">
    <parent link="finger2_left"/>
    <child link="finger2_phalanx_left"/>
    <origin rpy="0 1.57 0" xyz="0 0 -0.06"/>
  </joint>
  <joint name="finger2_tip_joint_left" type="revolute">
    <parent link="finger2_left"/>
    <child link="finger2_tip_left"/>
    <origin rpy="0 0 0" xyz="0 0 -0.06"/>
    <axis xyz="-1 0 0"/>
    <dynamics damping="0.5" friction="1.0"/>
    <limit effort="3" lower="-1.57" upper="1.57" velocity="1.0"/>
  </joint>
  <joint name="finger2_tip_phalanx_joint_left" type="fixed">
    <parent link="finger2_tip_left"/>
    <child link="finger2_tip_phalanx_left"/>
    <origin rpy="0 1.57 0" xyz="0 0 -0.06"/>
  </joint>
  <joint name="grippoint_joint_left" type="fixed">
    <parent link="hand_left"/>
    <child link="grippoint_left"/>
    <origin rpy="0 0 0" xyz="0.14 0.0 0.0"/>
  </joint>
  <author>Kris van Tienhoven, Janno Lunenburg</author>
  <license>BSD</license>
  <review notes="" status="unreviewed"/>
  <link name="head_mount">
    <inertial>
      <origin rpy="0 0 0" xyz="-0.0505 0.0 0.0"/>
      <mass value="0.05"/>
      <inertia ixx="0.0001" ixy="0" ixz="0" iyy="0.0001" iyz="0" izz="0.0001"/>
    </inertial>
    <visual>
      <origin rpy="0 0 0" xyz="-0.0505 0.0 0.0"/>
      <geometry>
        <box size="0.061 0.08 0.08"/>
      </geometry>
      <material name="White">
         </material>
    </visual>
    <collision>
      <origin rpy="0 0 0" xyz="-0.0505 0.0 0.0"/>
      <geometry>
        <box size="0.061 0.08 0.08"/>
      </geometry>
    </collision>
  </link>
  <joint name="head_mount_joint" type="fixed">
    <parent link="trunk"/>
    <child link="head_mount"/>
    <axis xyz="0 0 1"/>
    <origin rpy="3.14 0.065 0.0" xyz="0.6057 0.0 -0.01017"/>
    <!-- Check length -->
  </joint>
  <link name="neck_pan">
    <inertial>
      <origin rpy="0 0 0" xyz="0.0 0.0 -0.01"/>
      <mass value="0.05"/>
      <inertia ixx="0.0001" ixy="0" ixz="0" iyy="0.0001" iyz="0" izz="0.0001"/>
    </inertial>
    <visual>
      <origin rpy="0 0 0" xyz="0.0 0.0 -0.01"/>
      <geometry>
        <cylinder length="0.02" radius="0.015"/>
      </geometry>
      <material name="White">
         </material>
    </visual>
    <collision>
      <origin rpy="0 0 0" xyz="0.0 0.0 -0.01"/>
      <geometry>
        <cylinder length="0.02" radius="0.015"/>
      </geometry>
    </collision>
  </link>
  <link name="neck_tilt">
    <inertial>
      <origin rpy="0 0 0" xyz="0.0 -0.0 0.018"/>
      <mass value="0.05"/>
      <inertia ixx="0.001" ixy="0" ixz="0" iyy="0.001" iyz="0" izz="0.001"/>
    </inertial>
    <visual>
      <origin rpy="0 0 0" xyz="0.0 -0.0 0.018"/>
      <geometry>
        <box size="0.03 0.03 0.036"/>
      </geometry>
      <material name="White">
         </material>
    </visual>
    <collision>
      <origin rpy="0 0 0" xyz="0.0 -0.0 0.018"/>
      <geometry>
        <box size="0.03 0.03 0.036"/>
      </geometry>
    </collision>
  </link>
  <!--the head itself-->
  <!--<my_link_texturedmesh name="head" mass="0" texture="White">
   <origin xyz="0 0 0.041" rpy="0 0 0"/>
   <origin xyz="0.0 0.0 0.141" rpy="0 0 -1.5708"/>
   <inertia ixx="0"  ixy="0"  ixz="0" iyy="0" iyz="0" izz="0" /> 
   <mesh filename="package://sergio_description/media/meshes/headtextured.dae" scale="0.0004 0.0004 0.0004"/>
  </my_link_texturedmesh>-->
  <link name="head">
    <inertial>
      <origin rpy="0 0 0" xyz="0.0 0.0 0.041"/>
      <mass value="0"/>
      <inertia ixx="0" ixy="0" ixz="0" iyy="0" iyz="0" izz="0"/>
    </inertial>
    <visual>
      <origin rpy="0 0 -1.5708" xyz="0.0 0.0 0.141"/>
      <geometry>
        <box size="0.001 0.001 0.001"/>
      </geometry>
      <material name="White">
         </material>
    </visual>
    <collision>
      <origin rpy="0 0 -1.5708" xyz="0.0 0.0 0.141"/>
      <geometry>
        <box size="0.001 0.001 0.001"/>
      </geometry>
    </collision>
  </link>
  <joint name="head_joint" type="fixed">
    <parent link="neck_tilt"/>
    <child link="head"/>
    <origin rpy="0.0 0.0 0.0" xyz="0.0 0.0 0.036"/>
  </joint>
  <joint name="neck_pan_joint" type="revolute">
    <parent link="head_mount"/>
    <child link="neck_pan"/>
    <origin rpy="3.14 -1.5708 0.0" xyz="0.0 0.0 0.0"/>
    <axis xyz="0 0 1"/>
    <dynamics damping="0.1" friction="0"/>
    <limit effort="13.4" lower="-1.586" upper="1.586" velocity="1.0"/>
  </joint>
  <joint name="neck_tilt_joint" type="revolute">
    <parent link="neck_pan"/>
    <child link="neck_tilt"/>
    <origin rpy="0.0 0.0 0.0" xyz="0.0 0.0 0.0"/>
    <axis xyz="0 1 0"/>
    <dynamics damping="0.1" friction="0.0"/>
    <limit effort="13.4" lower="-0.994" upper="0.994" velocity="1.0"/>
  </joint>
  <joint name="top_kinect/base_kinect_joint" type="fixed">
    <origin rpy="0 0 0" xyz="0.03 0.0 0.017"/>
    <!-- THESE VALUES ARE ROUGH ESTIMATES!! -->
    <parent link="head"/>
    <child link="top_kinect/openni_camera"/>
  </joint>
  <link name="top_kinect/openni_camera">
    <inertial>
      <mass value="0.01"/>
      <origin xyz="0 0 0"/>
      <inertia ixx="0.001" ixy="0.0" ixz="0.0" iyy="0.001" iyz="0.0" izz="0.001"/>
    </inertial>
    <visual>
      <origin rpy="0 0 0" xyz=" 0 0 0 "/>
      <geometry>
        <!--<box size="0.001 0.001 0.001"/>-->
        <!--Changed to 0.001 because otherwise it doesn't work-->
        <!--mesh filename="package://sergio_description/kinect/meshes/kinect.dae" scale="0.001 0.001 0.001"/-->
        <mesh filename="package://sergio_description/media/meshes/kinect_without_base.dae"/>
      </geometry>
    </visual>
    <!--<collision>
      <origin xyz="-0.0365 0.0 0.0" rpy="0 0 0" />
      <geometry>
        <box size="0.0730 .2760 0.0720"/>
      </geometry>
    </collision>-->
  </link>
  <joint name="top_kinect/kinect_depth_joint" type="fixed">
    <origin rpy="0 0 0" xyz="0 0.018 0"/>
    <parent link="top_kinect/openni_camera"/>
    <child link="top_kinect/openni_depth_frame"/>
  </joint>
  <link name="top_kinect/openni_depth_frame">
    <inertial>
      <mass value="0.01"/>
      <origin xyz="0 0 0"/>
      <inertia ixx="0.001" ixy="0.0" ixz="0.0" iyy="0.001" iyz="0.0" izz="0.001"/>
    </inertial>
  </link>
  <joint name="top_kinect/kinect_depth_optical_joint" type="fixed">
    <origin rpy="-1.570795 0 -1.570795" xyz="0 0 0"/>
    <parent link="top_kinect/openni_depth_frame"/>
    <child link="top_kinect/openni_depth_optical_frame"/>
  </joint>
  <link name="top_kinect/openni_depth_optical_frame">
    <inertial>
      <mass value="0.001"/>
      <origin xyz="0 0 0"/>
      <inertia ixx="0.0001" ixy="0.0" ixz="0.0" iyy="0.0001" iyz="0.0" izz="0.0001"/>
    </inertial>
  </link>
  <joint name="top_kinect/kinect_rgb_joint" type="fixed">
    <origin rpy="0 0 0" xyz="0 -0.005 0"/>
    <parent link="top_kinect/openni_camera"/>
    <child link="top_kinect/openni_rgb_frame"/>
  </joint>
  <link name="top_kinect/openni_rgb_frame">
    <inertial>
      <mass value="0.001"/>
      <origin xyz="0 0 0"/>
      <inertia ixx="0.0001" ixy="0.0" ixz="0.0" iyy="0.0001" iyz="0.0" izz="0.0001"/>
    </inertial>
  </link>
  <joint name="top_kinect/kinect_rgb_optical_joint" type="fixed">
    <origin rpy="-1.570795 0 -1.570795" xyz="0 0 0"/>
    <parent link="top_kinect/openni_rgb_frame"/>
    <child link="top_kinect/openni_rgb_optical_frame"/>
  </joint>
  <link name="top_kinect/openni_rgb_optical_frame">
    <inertial>
      <mass value="0.001"/>
      <origin xyz="0 0 0"/>
      <inertia ixx="0.0001" ixy="0.0" ixz="0.0" iyy="0.0001" iyz="0.0" izz="0.0001"/>
    </inertial>
  </link>
  <author>Ton Peters</author>
  <license>BSD</license>
  <review notes="" status="unreviewed"/>
  <!-- joint origin of the laser range finder -->
  <joint name="base_lasercenter_joint" type="fixed">
    <parent link="laser_mount"/>
    <child link="base_laser"/>
    <origin rpy="0.0 0.0 0.0" xyz="0.03 0.0 0.06"/>
  </joint>
  <link name="base_laser">
    <inertial>
      <origin rpy="0 0 0" xyz="0.0 0.0 -0.026"/>
      <mass value="0.5"/>
      <inertia ixx="0.0001" ixy="0" ixz="0" iyy="0.0001" iyz="0" izz="0.0001"/>
    </inertial>
    <visual>
      <origin rpy="0 0 0" xyz="0.0 0.0 -0.026"/>
      <geometry>
        <box size="0.06 0.06 0.069"/>
      </geometry>
      <material name="Black">
         </material>
    </visual>
    <collision>
      <origin rpy="0 0 0" xyz="0.0 0.0 -0.026"/>
      <geometry>
        <box size="0.06 0.06 0.069"/>
      </geometry>
    </collision>
  </link>
  <!-- joint origin of the orange top -->
  <joint name="base_lasertop_joint" type="fixed">
    <parent link="base_laser"/>
    <child link="base_lasertop"/>
    <!--<origin xyz="0.0 0.0 0.023" rpy="0 0 0"/>-->
    <origin rpy="0 0 0" xyz="0.0 0.0 0.0175"/>
  </joint>
  <link name="base_lasertop">
    <inertial>
      <origin rpy="0 0 0" xyz="0.0 0.0 0.0"/>
      <mass value="0.01"/>
      <inertia ixx="0.0001" ixy="0" ixz="0" iyy="0.0001" iyz="0" izz="0.0001"/>
    </inertial>
    <visual>
      <origin rpy="0 0 0" xyz="0.0 0.0 0.0"/>
      <geometry>
        <box size="0.06 0.06 0.018"/>
      </geometry>
      <material name="Orange">
         </material>
    </visual>
    <collision>
      <origin rpy="0 0 0" xyz="0.0 0.0 0.0"/>
      <geometry>
        <box size="0.06 0.06 0.018"/>
      </geometry>
    </collision>
  </link>
  <!-- joint origin of the laser range finder -->
  <joint name="back_lasercenter_joint" type="fixed">
    <parent link="back_laser_mount"/>
    <child link="back_laser"/>
    <origin rpy="0.0 0.0 3.141592653589793" xyz="0.0 0.0 0.06"/>
  </joint>
  <link name="back_laser">
    <inertial>
      <origin rpy="0 0 0" xyz="0.0 0.0 -0.026"/>
      <mass value="0.5"/>
      <inertia ixx="0.0001" ixy="0" ixz="0" iyy="0.0001" iyz="0" izz="0.0001"/>
    </inertial>
    <visual>
      <origin rpy="0 0 0" xyz="0.0 0.0 -0.026"/>
      <geometry>
        <box size="0.06 0.06 0.069"/>
      </geometry>
      <material name="Black">
         </material>
    </visual>
    <collision>
      <origin rpy="0 0 0" xyz="0.0 0.0 -0.026"/>
      <geometry>
        <box size="0.06 0.06 0.069"/>
      </geometry>
    </collision>
  </link>
  <!-- joint origin of the orange top -->
  <joint name="back_lasertop_joint" type="fixed">
    <parent link="back_laser"/>
    <child link="back_lasertop"/>
    <!--<origin xyz="0.0 0.0 0.023" rpy="0 0 0"/>-->
    <origin rpy="0 0 0" xyz="0.0 0.0 0.0175"/>
  </joint>
  <link name="back_lasertop">
    <inertial>
      <origin rpy="0 0 0" xyz="0.0 0.0 0.0"/>
      <mass value="0.01"/>
      <inertia ixx="0.0001" ixy="0" ixz="0" iyy="0.0001" iyz="0" izz="0.0001"/>
    </inertial>
    <visual>
      <origin rpy="0 0 0" xyz="0.0 0.0 0.0"/>
      <geometry>
        <box size="0.06 0.06 0.018"/>
      </geometry>
      <material name="Orange">
         </material>
    </visual>
    <collision>
      <origin rpy="0 0 0" xyz="0.0 0.0 0.0"/>
      <geometry>
        <box size="0.06 0.06 0.018"/>
      </geometry>
    </collision>
  </link>
  <!-- joint origin of the laser range finder -->
  <joint name="torso_lasercenter_joint" type="fixed">
    <parent link="torso_laser_mount"/>
    <child link="torso_laser"/>
    <origin rpy="0.0 0.0 0.0" xyz="0.0 0.0 -0.004"/>
  </joint>
  <link name="torso_laser">
    <inertial>
      <origin rpy="0 0 0" xyz="0.0 0.0 -0.026"/>
      <mass value="0.5"/>
      <inertia ixx="0.0001" ixy="0" ixz="0" iyy="0.0001" iyz="0" izz="0.0001"/>
    </inertial>
    <visual>
      <origin rpy="0 0 0" xyz="0.0 0.0 -0.026"/>
      <geometry>
        <box size="0.06 0.06 0.069"/>
      </geometry>
      <material name="Black">
         </material>
    </visual>
    <collision>
      <origin rpy="0 0 0" xyz="0.0 0.0 -0.026"/>
      <geometry>
        <box size="0.06 0.06 0.069"/>
      </geometry>
    </collision>
  </link>
  <!-- joint origin of the orange top -->
  <joint name="torso_lasertop_joint" type="fixed">
    <parent link="torso_laser"/>
    <child link="torso_lasertop"/>
    <!--<origin xyz="0.0 0.0 0.023" rpy="0 0 0"/>-->
    <origin rpy="0 0 0" xyz="0.0 0.0 0.0175"/>
  </joint>
  <link name="torso_lasertop">
    <inertial>
      <origin rpy="0 0 0" xyz="0.0 0.0 0.0"/>
      <mass value="0.01"/>
      <inertia ixx="0.0001" ixy="0" ixz="0" iyy="0.0001" iyz="0" izz="0.0001"/>
    </inertial>
    <visual>
      <origin rpy="0 0 0" xyz="0.0 0.0 0.0"/>
      <geometry>
        <box size="0.06 0.06 0.018"/>
      </geometry>
      <material name="Orange">
         </material>
    </visual>
    <collision>
      <origin rpy="0 0 0" xyz="0.0 0.0 0.0"/>
      <geometry>
        <box size="0.06 0.06 0.018"/>
      </geometry>
    </collision>
  </link>
</robot>
